<?xml version="1.0" ?>
<!-- =================================================================================== -->
<!-- |    This document was autogenerated by xacro from hsr_co602_gripper_onhand_kinect2.xacro | -->
<!-- |    EDITING THIS FILE BY HAND IS NOT RECOMMENDED                                 | -->
<!-- =================================================================================== -->
<robot name="hsr_co602_gripper_onhand_kinect2" xmlns:xacro="http://www.ros.org/wiki/xacro">
  <link name="world"/>
  <joint name="fixed" type="fixed">
    <parent link="world"/>
    <child link="base_link"/>
    <origin rpy="0 0 0" xyz="0 0 1"/>
  </joint>
  <link name="base_link">
    <inertial>
      <origin rpy="0 0 0" xyz="-0.0024614 3.992E-07 0.076752"/>
      <mass value="4.8818"/>
      <inertia ixx="0.093861" ixy="-0.0058307" ixz="-2.7963E-06" iyy="0.080534" iyz="4.4333E-09" izz="0.12747"/>
    </inertial>
    <visual>
      <origin rpy="0 0 0" xyz="0 0 0"/>
      <geometry>
        <mesh filename="package://hsr_description/meshes/co602a/base_link.STL"/>
      </geometry>
      <material name="">
        <color rgba="0.1137 0.5098 0.97 1"/>
      </material>
    </visual>
    <collision>
      <origin rpy="0 0 0" xyz="0 0 0"/>
      <geometry>
        <mesh filename="package://hsr_description/meshes/co602a/base_link.STL"/>
      </geometry>
    </collision>
  </link>
  <link name="link1">
    <inertial>
      <origin rpy="0 0 0" xyz="-3.4523E-06 -0.02843 0.064536"/>
      <mass value="4.9839"/>
      <inertia ixx="0" ixy="0" ixz="0" iyy="0" iyz="0" izz="0"/>
    </inertial>
    <visual>
      <origin rpy="0 0 0" xyz="0 0 0"/>
      <geometry>
        <mesh filename="package://hsr_description/meshes/co602a/link1.STL"/>
      </geometry>
      <material name="">
        <color rgba="0.1137 0.5098 0.97 1"/>
      </material>
    </visual>
    <collision>
      <origin rpy="0 0 0" xyz="0 0 0"/>
      <geometry>
        <mesh filename="package://hsr_description/meshes/co602a/link1.STL"/>
      </geometry>
    </collision>
  </link>
  <joint name="joint_1" type="revolute">
    <origin rpy="3.1416 0 -3.4694E-18" xyz="0 0 0.352"/>
    <parent link="base_link"/>
    <child link="link1"/>
    <axis xyz="0 0 -1"/>
    <limit effort="28" lower="-3.490658503988" upper="3.490658503988" velocity="1.5"/>
    <safety_controller k_position="0" k_velocity="10" soft_lower_limit="-3.481931857728" soft_upper_limit="3.481931857728"/>
  </joint>
  <link name="link2">
    <inertial>
      <origin rpy="0 0 0" xyz="4.7574E-06 -0.18488 -0.037843"/>
      <mass value="6.6939"/>
      <inertia ixx="0" ixy="0" ixz="0" iyy="0" iyz="0" izz="0"/>
    </inertial>
    <visual>
      <origin rpy="0 0 0" xyz="0 0 0"/>
      <geometry>
        <mesh filename="package://hsr_description/meshes/co602a/link2.STL"/>
      </geometry>
      <material name="">
        <color rgba="0.97 0.7 0 1"/>
      </material>
    </visual>
    <collision>
      <origin rpy="0 0 0" xyz="0 0 0"/>
      <geometry>
        <mesh filename="package://hsr_description/meshes/co602a/link2.STL"/>
      </geometry>
    </collision>
  </link>
  <joint name="joint_2" type="revolute">
    <origin rpy="1.5708 -1.5708 0" xyz="0 0 0"/>
    <parent link="link1"/>
    <child link="link2"/>
    <axis xyz="0 0 1"/>
    <limit effort="28" lower="-2.268928027592" upper="1" velocity="1.0"/>
    <safety_controller k_position="100" k_velocity="10" soft_lower_limit="-2.260201381332" soft_upper_limit="1"/>
  </joint>
  <link name="link3">
    <inertial>
      <origin rpy="0 0 0" xyz="-4.098E-05 -0.085254 -0.035956"/>
      <mass value="2.3223"/>
      <inertia ixx="0" ixy="0" ixz="0" iyy="0" iyz="0" izz="0"/>
    </inertial>
    <visual>
      <origin rpy="0 0 0" xyz="0 0 0"/>
      <geometry>
        <mesh filename="package://hsr_description/meshes/co602a/link3.STL"/>
      </geometry>
      <material name="">
        <color rgba="0.1137 0.5098 0.97 1"/>
      </material>
    </visual>
    <collision>
      <origin rpy="0 0 0" xyz="0 0 0"/>
      <geometry>
        <mesh filename="package://hsr_description/meshes/co602a/link3.STL"/>
      </geometry>
    </collision>
  </link>
  <joint name="joint_3" type="revolute">
    <origin rpy="6.3741E-17 1.5386E-16 -1.5708" xyz="0 -0.4 0"/>
    <parent link="link2"/>
    <child link="link3"/>
    <axis xyz="0 0 1"/>
    <!--limit effort="28" lower="1" upper="3.665191429188" velocity="3.2"/-->
    <limit effort="28" lower="0.61" upper="3.665191429188" velocity="2.0"/>
    <safety_controller k_position="100" k_velocity="10" soft_lower_limit="0.008726646259" soft_upper_limit="3.656464782928"/>
  </joint>
  <link name="link4">
    <inertial>
      <origin rpy="0 0 0" xyz="0.049627 2.6934E-06 0.3246"/>
      <mass value="1.3111"/>
      <inertia ixx="0" ixy="0" ixz="0" iyy="0" iyz="0" izz="0"/>
    </inertial>
    <visual>
      <origin rpy="0 0 0" xyz="0 0 0"/>
      <geometry>
        <mesh filename="package://hsr_description/meshes/co602a/link4.STL"/>
      </geometry>
      <material name="">
        <color rgba="0.97 0.7 0 1"/>
      </material>
    </visual>
    <collision>
      <origin rpy="0 0 0" xyz="0 0 0"/>
      <geometry>
        <mesh filename="package://hsr_description/meshes/co602a/link4.STL"/>
      </geometry>
    </collision>
  </link>
  <joint name="joint_4" type="revolute">
    <origin rpy="1.5708 1.5708 0" xyz="0 0 0"/>
    <parent link="link3"/>
    <child link="link4"/>
    <axis xyz="0 0 1"/>
    <limit effort="28" lower="-2.1" upper="2.1" velocity="2.0"/>
    <safety_controller k_position="100" k_velocity="10" soft_lower_limit="-3.132866007329" soft_upper_limit="3.132866007329"/>
  </joint>
  <link name="link5">
    <inertial>
      <origin rpy="0 0 0" xyz="1.2952E-06 -0.043824 0.0021728"/>
      <mass value="1.1683"/>
      <inertia ixx="0" ixy="0" ixz="0" iyy="0" iyz="0" izz="0"/>
    </inertial>
    <visual>
      <origin rpy="0 0 0" xyz="0 0 0"/>
      <geometry>
        <mesh filename="package://hsr_description/meshes/co602a/link5.STL"/>
      </geometry>
      <material name="">
        <color rgba="0.113 0.5098 0.7 1"/>
      </material>
    </visual>
    <collision>
      <origin rpy="0 0 0" xyz="0 0 0"/>
      <geometry>
        <mesh filename="package://hsr_description/meshes/co602a/link5.STL"/>
      </geometry>
    </collision>
  </link>
  <joint name="joint_5" type="revolute">
    <origin rpy="-1.5708 1.8044E-17 1.5708" xyz="0 0 0.39901"/>
    <parent link="link4"/>
    <child link="link5"/>
    <axis xyz="0 0 1"/>
    <limit effort="28" lower="-2.268928027592" upper="2.268928027592" velocity="2.0"/>
    <safety_controller k_position="0" k_velocity="10" soft_lower_limit="-2.260201381332" soft_upper_limit="2.260201381332"/>
  </joint>
  <link name="link6">
    <inertial>
      <origin rpy="0 0 0" xyz="-3.5784E-05 3.8806E-05 -0.025197"/>
      <mass value="0.20458"/>
      <inertia ixx="0" ixy="0" ixz="0" iyy="0" iyz="0" izz="0"/>
    </inertial>
    <visual>
      <origin rpy="0 0 0" xyz="0 0 0"/>
      <geometry>
        <mesh filename="package://hsr_description/meshes/co602a/link6.STL"/>
      </geometry>
      <material name="">
        <color rgba="0.113 0.5098 0.7 1"/>
      </material>
    </visual>
    <collision>
      <origin rpy="0 0 0" xyz="0 0 0"/>
      <geometry>
        <mesh filename="package://hsr_description/meshes/co602a/link6.STL"/>
      </geometry>
    </collision>
  </link>
  <joint name="joint_6" type="revolute">
    <origin rpy="-1.5708 1.0064E-16 -3.1416" xyz="0 -0.19849 0"/>
    <parent link="link5"/>
    <child link="link6"/>
    <axis xyz="0 0 1"/>
    <limit effort="28" lower="-3.490658504" upper="1.4015" velocity="2.0"/>
    <safety_controller k_position="0" k_velocity="10" soft_lower_limit="-6.274458660919" soft_upper_limit="6.274458660919"/>
  </joint>
  <gazebo>
    <plugin filename="libgazebo_ros_control.so" name="gazebo_ros_control">
      <robotNamespace>/</robotNamespace>
      <robotSimType>gazebo_ros_control/DefaultRobotHWSim</robotSimType>
    </plugin>
  </gazebo>
  <transmission name="tran1">
    <type>transmission_interface/SimpleTransmission</type>
    <joint name="joint_1">
      <hardwareInterface>PositionJointInterface</hardwareInterface>
    </joint>
    <actuator name="motor1">
      <hardwareInterface>PositionJointInterface</hardwareInterface>
      <mechanicalReduction>1</mechanicalReduction>
    </actuator>
  </transmission>
  <transmission name="tran2">
    <type>transmission_interface/SimpleTransmission</type>
    <joint name="joint_2">
      <hardwareInterface>PositionJointInterface</hardwareInterface>
    </joint>
    <actuator name="motor2">
      <hardwareInterface>PositionJointInterface</hardwareInterface>
      <mechanicalReduction>1</mechanicalReduction>
    </actuator>
  </transmission>
  <transmission name="tran3">
    <type>transmission_interface/SimpleTransmission</type>
    <joint name="joint_3">
      <hardwareInterface>PositionJointInterface</hardwareInterface>
    </joint>
    <actuator name="motor3">
      <hardwareInterface>PositionJointInterface</hardwareInterface>
      <mechanicalReduction>1</mechanicalReduction>
    </actuator>
  </transmission>
  <transmission name="tran4">
    <type>transmission_interface/SimpleTransmission</type>
    <joint name="joint_4">
      <hardwareInterface>PositionJointInterface</hardwareInterface>
    </joint>
    <actuator name="motor4">
      <hardwareInterface>PositionJointInterface</hardwareInterface>
      <mechanicalReduction>1</mechanicalReduction>
    </actuator>
  </transmission>
  <transmission name="tran5">
    <type>transmission_interface/SimpleTransmission</type>
    <joint name="joint_5">
      <hardwareInterface>PositionJointInterface</hardwareInterface>
    </joint>
    <actuator name="motor5">
      <hardwareInterface>PositionJointInterface</hardwareInterface>
      <mechanicalReduction>1</mechanicalReduction>
    </actuator>
  </transmission>
  <transmission name="tran6">
    <type>transmission_interface/SimpleTransmission</type>
    <joint name="joint_6">
      <hardwareInterface>PositionJointInterface</hardwareInterface>
    </joint>
    <actuator name="motor6">
      <hardwareInterface>PositionJointInterface</hardwareInterface>
      <mechanicalReduction>1</mechanicalReduction>
    </actuator>
  </transmission>
  <!-- Size of square 'camera' box -->
  <link name="camera_link">
    <collision>
      <origin rpy="0 0 0" xyz="0 0 0"/>
      <geometry>
        <box size="0.05 0.05 0.05"/>
      </geometry>
    </collision>
    <visual>
      <origin rpy="0 0 0" xyz="0 0 0"/>
      <geometry>
        <box size="0.05 0.05 0.05"/>
      </geometry>
      <material name="red"/>
    </visual>
    <inertial>
      <mass value="1e-5"/>
      <origin rpy="0 0 0" xyz="0 0 0"/>
      <inertia ixx="1e-6" ixy="0" ixz="0" iyy="1e-6" iyz="0" izz="1e-6"/>
    </inertial>
  </link>
  <!-- kinect -->
  <gazebo reference="camera_link">
    <sensor name="openni_camera_camera" type="depth">
      <always_on>1</always_on>
      <visualize>true</visualize>
      <camera>
        <horizontal_fov>1.047</horizontal_fov>
        <image>
          <width>640</width>
          <height>480</height>
          <format>B8G8R8</format>
        </image>
        <depth_camera>

            </depth_camera>
        <clip>
          <near>0.1</near>
          <far>100</far>
        </clip>
      </camera>
      <plugin filename="libgazebo_ros_openni_kinect.so" name="camera_controller">
        <alwaysOn>true</alwaysOn>
        <baseline>0.2</baseline>
        <updateRate>30</updateRate>
        <cameraName>camera</cameraName>
        <frameName>kinect_frame</frameName>
        <imageTopicName>rgb/image_raw</imageTopicName>
        <depthImageTopicName>depth/image_raw</depthImageTopicName>
        <pointCloudTopicName>depth/points</pointCloudTopicName>
        <cameraInfoTopicName>rgb/camera_info</cameraInfoTopicName>
        <depthImageCameraInfoTopicName>depth/camera_info</depthImageCameraInfoTopicName>
        <pointCloudCutoff>0.5</pointCloudCutoff>
        <distortionK1>0</distortionK1>
        <distortionK2>0</distortionK2>
        <distortionK3>0</distortionK3>
        <distortionT1>0</distortionT1>
        <distortionT2>0</distortionT2>
        <CxPrime>0.0</CxPrime>
        <Cx>0.0</Cx>
        <Cy>0.0</Cy>
        <focalLength>0.0</focalLength>
      </plugin>
    </sensor>
  </gazebo>
  <link name="gripper_base_link">
    <inertial>
      <origin rpy="0 0 0" xyz="0.000131706391042187 -0.0390683856464977 0.081199520192839"/>
      <mass value="0.145677232438391"/>
      <inertia ixx="8.40495062422861E-05" ixy="-6.82136717259575E-07" ixz="9.08788702310012E-07" iyy="4.96036917958725E-05" iyz="3.95062698042515E-05" izz="3.44803015215572E-05"/>
    </inertial>
    <visual>
      <origin rpy="0 0 0" xyz="0 0 0"/>
      <geometry>
        <mesh filename="package://hsr_description/meshes/eye_hand_gripper/base_link.STL"/>
      </geometry>
      <material name="">
        <color rgba="0.4 0.4 0.35 1"/>
      </material>
    </visual>
    <collision>
      <origin rpy="0 0 0" xyz="0 0 0"/>
      <geometry>
        <mesh filename="package://hsr_description/meshes/eye_hand_gripper/base_link.STL"/>
      </geometry>
    </collision>
  </link>
  <link name="grisper_boby_link">
    <inertial>
      <origin rpy="0 0 0" xyz="2.84228059294067E-05 -0.000875529500481004 -0.00997402814116276"/>
      <mass value="0.0387962759306602"/>
      <inertia ixx="0" ixy="0" ixz="0" iyy="0" iyz="0" izz="0"/>
    </inertial>
    <visual>
      <origin rpy="0 0 0" xyz="0 0 0"/>
      <geometry>
        <mesh filename="package://hsr_description/meshes/eye_hand_gripper/grisper_boby_link.STL"/>
      </geometry>
      <material name="">
        <color rgba="0.4 0.55 0.35 1"/>
      </material>
    </visual>
    <collision>
      <origin rpy="0 0 0" xyz="0 0 0"/>
      <geometry>
        <mesh filename="package://hsr_description/meshes/eye_hand_gripper/grisper_boby_link.STL"/>
      </geometry>
    </collision>
  </link>
  <joint name="grisper_boby_joint" type="fixed">
    <origin rpy="1.5708 1.3479E-15 1.3852E-15" xyz="0 -0.01 0.064"/>
    <parent link="gripper_base_link"/>
    <child link="grisper_boby_link"/>
    <axis xyz="0 0 0"/>
  </joint>
  <link name="right_finger_1_link">
    <inertial>
      <origin rpy="0 0 0" xyz="-2.92388038200531E-06 0.0168231601122346 0.0089790044607883"/>
      <mass value="0.00235032514171626"/>
      <inertia ixx="0" ixy="0" ixz="0" iyy="0" iyz="0" izz="0"/>
    </inertial>
    <visual>
      <origin rpy="0 0 0" xyz="0 0 0"/>
      <geometry>
        <mesh filename="package://hsr_description/meshes/eye_hand_gripper/right_finger_1_link.STL"/>
      </geometry>
      <material name="">
        <color rgba="0.4 0.55 0.35 1"/>
      </material>
    </visual>
    <collision>
      <origin rpy="0 0 0" xyz="0 0 0"/>
      <geometry>
        <mesh filename="package://hsr_description/meshes/eye_hand_gripper/right_finger_1_link.STL"/>
      </geometry>
    </collision>
  </link>
  <joint name="right_finger_1_joint" type="continuous">
    <origin rpy="0 0 -0.501740656078991" xyz="0.04 0.036 -0.019"/>
    <parent link="grisper_boby_link"/>
    <child link="right_finger_1_link"/>
    <axis xyz="0 0 1"/>
  </joint>
  <link name="right_finger_2_link">
    <inertial>
      <origin rpy="0 0 0" xyz="-0.0085798133911776 0.00661394976740351 0.00600000756322747"/>
      <mass value="0.00200167864656235"/>
      <inertia ixx="0" ixy="0" ixz="0" iyy="0" iyz="0" izz="0"/>
    </inertial>
    <visual>
      <origin rpy="0 0 0" xyz="0 0 0"/>
      <geometry>
        <mesh filename="package://hsr_description/meshes/eye_hand_gripper/right_finger_2_link.STL"/>
      </geometry>
      <material name="">
        <color rgba="0.4 0.55 0.35 1"/>
      </material>
    </visual>
    <collision>
      <origin rpy="0 0 0" xyz="0 0 0"/>
      <geometry>
        <mesh filename="package://hsr_description/meshes/eye_hand_gripper/right_finger_2_link.STL"/>
      </geometry>
    </collision>
  </link>
  <joint name="right_finger_2_joint" type="continuous">
    <origin rpy="0 0 0.501740656078991" xyz="0 0.042 0.00300000000000001"/>
    <parent link="right_finger_1_link"/>
    <child link="right_finger_2_link"/>
    <axis xyz="0 0 1"/>
  </joint>
  <link name="right_finger_end_link">
    <inertial>
      <origin rpy="0 0 0" xyz="-0.0181096606742553 0.00899999232533871 0.000419374358405108"/>
      <mass value="0.00169081070175499"/>
      <inertia ixx="0" ixy="0" ixz="0" iyy="0" iyz="0" izz="0"/>
    </inertial>
    <visual>
      <origin rpy="0 0 0" xyz="0 0 0"/>
      <geometry>
        <mesh filename="package://hsr_description/meshes/eye_hand_gripper/right_finger_end_link.STL"/>
      </geometry>
      <material name="">
        <color rgba="0.4 0.55 0.35 1"/>
      </material>
    </visual>
    <collision>
      <origin rpy="0 0 0" xyz="0 0 0"/>
      <geometry>
        <mesh filename="package://hsr_description/meshes/eye_hand_gripper/right_finger_end_link.STL"/>
      </geometry>
    </collision>
  </link>
  <joint name="right_finger_end_joint" type="fixed">
    <origin rpy="1.5707963267949 0 -1.5707963267949" xyz="-0.0145 -0.0035 -0.00300000000000001"/>
    <parent link="right_finger_2_link"/>
    <child link="right_finger_end_link"/>
    <axis xyz="0 0 0"/>
  </joint>
  <link name="left_finger_1_link">
    <inertial>
      <origin rpy="0 0 0" xyz="-2.92395601426965E-06 0.0168231599777492 0.00897900452955606"/>
      <mass value="0.0023503251697047"/>
      <inertia ixx="0" ixy="0" ixz="0" iyy="0" iyz="0" izz="0"/>
    </inertial>
    <visual>
      <origin rpy="0 0 0" xyz="0 0 0"/>
      <geometry>
        <mesh filename="package://hsr_description/meshes/eye_hand_gripper/left_finger_1_link.STL"/>
      </geometry>
      <material name="">
        <color rgba="0.4 0.55 0.35 1"/>
      </material>
    </visual>
    <collision>
      <origin rpy="0 0 0" xyz="0 0 0"/>
      <geometry>
        <mesh filename="package://hsr_description/meshes/eye_hand_gripper/left_finger_1_link.STL"/>
      </geometry>
    </collision>
  </link>
  <joint name="left_finger_1_joint" type="continuous">
    <origin rpy="0 0 0.501740656078991" xyz="-0.04 0.036 -0.019"/>
    <parent link="grisper_boby_link"/>
    <child link="left_finger_1_link"/>
    <axis xyz="0 0 1"/>
  </joint>
  <link name="left_finger_2_link">
    <inertial>
      <origin rpy="0 0 0" xyz="-0.00857981339117761 0.00661394976740348 0.00600000756322748"/>
      <mass value="0.00200167864656235"/>
      <inertia ixx="0" ixy="0" ixz="0" iyy="0" iyz="0" izz="0"/>
    </inertial>
    <visual>
      <origin rpy="0 0 0" xyz="0 0 0"/>
      <geometry>
        <mesh filename="package://hsr_description/meshes/eye_hand_gripper/left_finger_2_link.STL"/>
      </geometry>
      <material name="">
        <color rgba="0.4 0.55 0.35 1"/>
      </material>
    </visual>
    <collision>
      <origin rpy="0 0 0" xyz="0 0 0"/>
      <geometry>
        <mesh filename="package://hsr_description/meshes/eye_hand_gripper/left_finger_2_link.STL"/>
      </geometry>
    </collision>
  </link>
  <joint name="left_finger_2_joint" type="continuous">
    <origin rpy="3.14159265358979 0 2.6398519975108" xyz="0 0.0419999999999999 0.0149999999999995"/>
    <parent link="left_finger_1_link"/>
    <child link="left_finger_2_link"/>
    <axis xyz="0 0 1"/>
  </joint>
  <link name="left_finger_end_link">
    <inertial>
      <origin rpy="0 0 0" xyz="-0.0181096606742553 0.00899999232533872 0.000419374358405097"/>
      <mass value="0.00169081070175499"/>
      <inertia ixx="0" ixy="0" ixz="0" iyy="0" iyz="0" izz="0"/>
    </inertial>
    <visual>
      <origin rpy="0 0 0" xyz="0 0 0"/>
      <geometry>
        <mesh filename="package://hsr_description/meshes/eye_hand_gripper/left_finger_end_link.STL"/>
      </geometry>
      <material name="">
        <color rgba="0.4 0.55 0.35 1"/>
      </material>
    </visual>
    <collision>
      <origin rpy="0 0 0" xyz="0 0 0"/>
      <geometry>
        <mesh filename="package://hsr_description/meshes/eye_hand_gripper/left_finger_end_link.STL"/>
      </geometry>
    </collision>
  </link>
  <joint name="left_finger_end_joint" type="fixed">
    <origin rpy="1.5707963267949 8.67361737988403E-17 -1.5707963267949" xyz="-0.0144999999999999 -0.0035 -0.00299999999999996"/>
    <parent link="left_finger_2_link"/>
    <child link="left_finger_end_link"/>
    <axis xyz="0 0 0"/>
  </joint>
  <link name="pick_gripper_link">
    <visual>
      <origin rpy="0 0 0" xyz="0 0 0"/>
      <geometry>
        <box size="0.001 0.0005 0.0005"/>
      </geometry>
    </visual>
  </link>
  <transmission name="tran1">
    <type>transmission_interface/SimpleTransmission</type>
    <joint name="right_finger_1_joint">
      <hardwareInterface>PositionJointInterface</hardwareInterface>
    </joint>
    <actuator name="right_finger_1_motor">
      <hardwareInterface>PositionJointInterface</hardwareInterface>
      <mechanicalReduction>1</mechanicalReduction>
    </actuator>
  </transmission>
  <transmission name="tran2">
    <type>transmission_interface/SimpleTransmission</type>
    <joint name="right_finger_2_joint">
      <hardwareInterface>PositionJointInterface</hardwareInterface>
    </joint>
    <actuator name="right_finger_2_motor">
      <hardwareInterface>PositionJointInterface</hardwareInterface>
      <mechanicalReduction>1</mechanicalReduction>
    </actuator>
  </transmission>
  <transmission name="tran3">
    <type>transmission_interface/SimpleTransmission</type>
    <joint name="left_finger_1_joint">
      <hardwareInterface>PositionJointInterface</hardwareInterface>
    </joint>
    <actuator name="left_finger_1_motor">
      <hardwareInterface>PositionJointInterface</hardwareInterface>
      <mechanicalReduction>1</mechanicalReduction>
    </actuator>
  </transmission>
  <transmission name="tran4">
    <type>transmission_interface/SimpleTransmission</type>
    <joint name="left_finger_2_joint">
      <hardwareInterface>PositionJointInterface</hardwareInterface>
    </joint>
    <actuator name="left_finger_2_motor">
      <hardwareInterface>PositionJointInterface</hardwareInterface>
      <mechanicalReduction>1</mechanicalReduction>
    </actuator>
  </transmission>
  <hsr_co602a/>
  <joint name="gripper_robot_joint" type="fixed">
    <parent link="link6"/>
    <child link="gripper_base_link"/>
    <origin rpy="0 0 3.3161255788" xyz="0.0 0.0 0.0"/>
  </joint>
  <joint name="pick_gripper_joint" type="fixed">
    <origin rpy="0 -1.5708 1.5708" xyz="-0.0115 0.0 0.15"/>
    <axis xyz="0 0 1"/>
    <parent link="gripper_base_link"/>
    <child link="pick_gripper_link"/>
  </joint>
  <joint name="kinect_base_link_joint" type="fixed">
    <origin rpy=" 0 0 0" xyz="-0.3380248810871023 -0.6770877313845074 0.7103267987611978"/>
    <parent link="base_link"/>
    <child link="camera_link"/>
  </joint>
</robot>

