<?xml version="1.0"?>

<robot name="hsr_gripper" xmlns:xacro="http://ros.org/wiki/xacro">

	<joint name="gripper_base_joint" type="fixed">
	  <parent link="link6" />
    	  <child link="gripper_base_link" />
	  <origin xyz="0.0 0.0 -0.03" rpy="-1.57 1.57 0" />
	</joint>

	<link name="gripper_base_link">
	      <inertial>
		<mass value="0.00001" />
		<origin xyz="0 0 0" />
		<inertia ixx="1.0" ixy="0.0" ixz="0.0"
		  iyy="1.0" iyz="0.0"
		  izz="1.0" />
	      </inertial>

	      <visual>
		<origin xyz=" 0 0 0 " rpy="0 0 0" />
		<geometry>
		  <mesh filename="package://rbx2_description/meshes/ax12.stl" scale="0.001 0.001 0.001"/>
		</geometry>
		<material name="Red"/>
	      </visual>

	      <collision>
		<origin xyz="0.0 0.0 -0.01241" rpy="0 0 0" />
		<geometry>
		  <box size="0.025 0.038 0.04762"/>
		</geometry>
	      </collision>
	</link>

	  <joint name="gripper_active_finger_bracket_joint" type="revolute">
	      <origin xyz="0 0 0" rpy="0 0 0"/>
	      <axis xyz="0 1 0"/>
	      <limit effort="1.0" velocity="3.14" lower="-0.8" upper="0.5" />
	      <parent link="gripper_base_link"/>
	      <child link="gripper_active_finger_bracket_link" />
	   </joint>

	<link name="gripper_active_finger_bracket_link">
	      <inertial>
		<mass value="0.00001" />
		<origin xyz="0 0 0" />
		<inertia ixx="1.0" ixy="0.0" ixz="0.0"
		  iyy="1.0" iyz="0.0"
		  izz="1.0" />
	      </inertial>
	      
	      <visual>
		<origin xyz="0 0 0" rpy="0 0 0" />
		<geometry>
		  <mesh filename="package://rbx2_description/meshes/F2.stl" scale="0.001 0.001 0.001"/>
		</geometry>
		<material name="Green">
		  <color rgba="0 1 0 1" />
		</material>
	      </visual>
	      
	      <collision>
		<origin xyz="0.0 0.0 0.00775" rpy="0 0 0" />
		<geometry>
		  <box size="0.025 0.0485 0.0375"/>
		</geometry>
	      </collision>
	</link>


	  <joint name="gripper_active_finger_joint" type="fixed">
	      <origin xyz="0 0 0.025" rpy="0 0 0"/>
	      <axis xyz="0 1 0"/>
	      <limit effort="1.0" velocity="3.14" lower="-0.8" upper="0.5" />
	      <parent link="gripper_active_finger_bracket_link"/>
	      <child link="gripper_active_finger_link" />	
	   </joint>

	    <link name="gripper_active_finger_link">
	      <inertial>
		<mass value="0.00001" />
		<origin xyz="0 0 0" />
		<inertia ixx="1.0" ixy="0.0" ixz="0.0"
		  iyy="1.0" iyz="0.0"
		  izz="1.0" />
	      </inertial>

	      <visual>
		<origin xyz=" 0 0 0 " rpy="0 0 0" />
		<geometry>
		  <mesh filename="package://rbx2_description/meshes/finger.stl" scale="0.001 0.001 0.001"/>
		</geometry>
		<material name="Green">
		<color rgba="0 1 0 1" />
		</material>
	      </visual>

	      <collision>
		<origin xyz="0.02645 0.0 -0.00655" rpy="0 0 0" />
		<geometry>
		  <box size="0.0783 0.03801 0.0193"/>
		</geometry>
	      </collision>
	    </link>

	   <joint name="gripper_fixed_finger_bracket_joint" type="fixed">
	      <origin xyz="0 0 0" rpy="0 0 0"/>
	      <parent link="gripper_base_link"/>
	      <child link="gripper_fixed_finger_bracket_link" />
	   </joint>

	    <link name="gripper_fixed_finger_bracket_link">
	      <inertial>
		<mass value="0.00001" />
		<origin xyz="0 0 0" />
		<inertia ixx="1.0" ixy="0.0" ixz="0.0"
		  iyy="1.0" iyz="0.0"
		  izz="1.0" />
	      </inertial>

	      <visual>
		<origin xyz=" 0 0 -0.04 " rpy="0 3.14 0" />
		<geometry>
		  <mesh filename="package://rbx2_description/meshes/F3.stl" scale="0.001 0.001 0.001"/>
		</geometry>
		<material name="Green"/>
	      </visual>

	      <collision>
		<origin xyz="0.0 0.0 -0.0045" rpy="0 0 0" />
		<geometry>
		  <box size="0.025 0.038 0.009"/>
		</geometry>
	      </collision>
	    </link>

	   <joint name="gripper_fixed_finger_joint" type="fixed">
	      <origin xyz="0 0 -0.04" rpy="3.14 0 0"/>
	      <parent link="gripper_fixed_finger_bracket_link"/>
	      <child link="gripper_fixed_finger_link" />
	   </joint>

	    <link name="gripper_fixed_finger_link">
	      <inertial>
		<mass value="0.00001" />
		<origin xyz="0 0 0" />
		<inertia ixx="1.0" ixy="0.0" ixz="0.0"
		  iyy="1.0" iyz="0.0"
		  izz="1.0" />
	      </inertial>

	      <visual>
		<origin xyz=" 0 0 0 " rpy="0 0 0" />
		<geometry>
		  <mesh filename="package://rbx2_description/meshes/finger.stl" scale="0.001 0.001 0.001"/>
		</geometry>
		<material name="Green">
		<color rgba="0 1 0 1" />
		</material>
	      </visual>

	      <collision>
		<origin xyz="0.02645 0.0 -0.00655" rpy="0 0 0" />
		<geometry>
		  <box size="0.0783 0.03801 0.0193"/>
		</geometry>
	      </collision>
	    </link>

	   <joint name="gripper_joint" type="fixed">
	      <origin xyz="0.05 0 -0.01" rpy="1.57 0 0"/>
	      <parent link="gripper_base_link"/>
	      <child link="gripper_link" />
	   </joint>

	    <link name="gripper_link">
	      <inertial>
		<mass value="0.00001" />
		<origin xyz="0 0 0" />
		<inertia ixx="1.0" ixy="0.0" ixz="0.0"
		  iyy="1.0" iyz="0.0"
		  izz="1.0" />
	      </inertial>

	      <visual>
		<origin xyz=" 0 0 0 " rpy="0 0 0" />
		<geometry>
		  <box size="0.00001 0.00001 0.00001"/>
		</geometry>
		<material name="Green">
		<color rgba="0 1 0 1" />
		</material>
	      </visual>
	      <collision>
		<origin xyz="0.02645 0.0 -0.00655" rpy="0 0 0" />
		<geometry>
		  <box size="0.00001 0.00001 0.00001"/>
		</geometry>
	      </collision>
	    </link>

  <transmission name="tran7">
    <type>transmission_interface/SimpleTransmission</type>
    <joint name="gripper_active_finger_bracket_joint">
      <hardwareInterface>PositionJointInterface</hardwareInterface>
    </joint>
    <actuator name="motor7">
      <hardwareInterface>PositionJointInterface</hardwareInterface>
      <mechanicalReduction>1</mechanicalReduction>
    </actuator>
  </transmission>

</robot>
