<?xml version="1.0" ?>
<!-- =================================================================================== -->
<!-- |    This document was autogenerated by xacro from hsr_co605_fight.xacro          | -->
<!-- |    EDITING THIS FILE BY HAND IS NOT RECOMMENDED                                 | -->
<!-- =================================================================================== -->
<robot name="hsr_co602_fight" xmlns:xacro="http://ros.org/wiki/xacro">
  <link name="world"/>
  <joint name="fixed" type="fixed">
    <parent link="world"/>
    <child link="base_link"/>
    <origin rpy="0 0 0" xyz="0 0 1"/>
  </joint>
  <link name="base_link">
    <inertial>
      <origin rpy="0 0 0" xyz="-0.0024614 3.992E-07 0.076752"/>
      <mass value="4.8818"/>
      <inertia ixx="0.093861" ixy="-0.0058307" ixz="-2.7963E-06" iyy="0.080534" iyz="4.4333E-09" izz="0.12747"/>
    </inertial>
    <visual>
      <origin rpy="0 0 0" xyz="0 0 0"/>
      <geometry>
        <mesh filename="package://hsr_description/meshes/co602a/base_link.STL"/>
      </geometry>
      <material name="">
        <color rgba="0.1137 0.5098 0.97 1"/>
      </material>
    </visual>
    <collision>
      <origin rpy="0 0 0" xyz="0 0 0"/>
      <geometry>
        <mesh filename="package://hsr_description/meshes/co602a/base_link.STL"/>
      </geometry>
    </collision>
  </link>
  <link name="link1">
    <inertial>
      <origin rpy="0 0 0" xyz="-3.4523E-06 -0.02843 0.064536"/>
      <mass value="4.9839"/>
      <inertia ixx="0" ixy="0" ixz="0" iyy="0" iyz="0" izz="0"/>
    </inertial>
    <visual>
      <origin rpy="0 0 0" xyz="0 0 0"/>
      <geometry>
        <mesh filename="package://hsr_description/meshes/co602a/link1.STL"/>
      </geometry>
      <material name="">
        <color rgba="0.1137 0.5098 0.97 1"/>
      </material>
    </visual>
    <collision>
      <origin rpy="0 0 0" xyz="0 0 0"/>
      <geometry>
        <mesh filename="package://hsr_description/meshes/co602a/link1.STL"/>
      </geometry>
    </collision>
  </link>
  <joint name="joint_1" type="revolute">
    <origin rpy="3.1416 0 -3.4694E-18" xyz="0 0 0.352"/>
    <parent link="base_link"/>
    <child link="link1"/>
    <axis xyz="0 0 -1"/>
    <limit effort="28" lower="-3.490658503988" upper="3.490658503988" velocity="3.2"/>
    <safety_controller k_position="100" k_velocity="10" soft_lower_limit="-3.481931857728" soft_upper_limit="3.481931857728"/>
  </joint>
  <link name="link2">
    <inertial>
      <origin rpy="0 0 0" xyz="4.7574E-06 -0.18488 -0.037843"/>
      <mass value="6.6939"/>
      <inertia ixx="0" ixy="0" ixz="0" iyy="0" iyz="0" izz="0"/>
    </inertial>
    <visual>
      <origin rpy="0 0 0" xyz="0 0 0"/>
      <geometry>
        <mesh filename="package://hsr_description/meshes/co602a/link2.STL"/>
      </geometry>
      <material name="">
        <color rgba="0.97 0.7 0 1"/>
      </material>
    </visual>
    <collision>
      <origin rpy="0 0 0" xyz="0 0 0"/>
      <geometry>
        <mesh filename="package://hsr_description/meshes/co602a/link2.STL"/>
      </geometry>
    </collision>
  </link>
  <joint name="joint_2" type="revolute">
    <origin rpy="1.5708 -1.5708 0" xyz="0 0 0"/>
    <parent link="link1"/>
    <child link="link2"/>
    <axis xyz="0 0 1"/>
    <limit effort="28" lower="-2.268928027592" upper="1" velocity="3.2"/>
    <safety_controller k_position="100" k_velocity="10" soft_lower_limit="-2.260201381332" soft_upper_limit="1"/>
  </joint>
  <link name="link3">
    <inertial>
      <origin rpy="0 0 0" xyz="-4.098E-05 -0.085254 -0.035956"/>
      <mass value="2.3223"/>
      <inertia ixx="0" ixy="0" ixz="0" iyy="0" iyz="0" izz="0"/>
    </inertial>
    <visual>
      <origin rpy="0 0 0" xyz="0 0 0"/>
      <geometry>
        <mesh filename="package://hsr_description/meshes/co602a/link3.STL"/>
      </geometry>
      <material name="">
        <color rgba="0.1137 0.5098 0.97 1"/>
      </material>
    </visual>
    <collision>
      <origin rpy="0 0 0" xyz="0 0 0"/>
      <geometry>
        <mesh filename="package://hsr_description/meshes/co602a/link3.STL"/>
      </geometry>
    </collision>
  </link>
  <joint name="joint_3" type="revolute">
    <origin rpy="6.3741E-17 1.5386E-16 -1.5708" xyz="0 -0.4 0"/>
    <parent link="link2"/>
    <child link="link3"/>
    <axis xyz="0 0 1"/>
    <limit effort="28" lower="1" upper="3.665191429188" velocity="3.2"/>
    <safety_controller k_position="100" k_velocity="10" soft_lower_limit="0.008726646259" soft_upper_limit="3.656464782928"/>
  </joint>
  <link name="link4">
    <inertial>
      <origin rpy="0 0 0" xyz="0.049627 2.6934E-06 0.3246"/>
      <mass value="1.3111"/>
      <inertia ixx="0" ixy="0" ixz="0" iyy="0" iyz="0" izz="0"/>
    </inertial>
    <visual>
      <origin rpy="0 0 0" xyz="0 0 0"/>
      <geometry>
        <mesh filename="package://hsr_description/meshes/co602a/link4.STL"/>
      </geometry>
      <material name="">
        <color rgba="0.97 0.7 0 1"/>
      </material>
    </visual>
    <collision>
      <origin rpy="0 0 0" xyz="0 0 0"/>
      <geometry>
        <mesh filename="package://hsr_description/meshes/co602a/link4.STL"/>
      </geometry>
    </collision>
  </link>
  <joint name="joint_4" type="revolute">
    <origin rpy="1.5708 1.5708 0" xyz="0 0 0"/>
    <parent link="link3"/>
    <child link="link4"/>
    <axis xyz="0 0 1"/>
    <limit effort="28" lower="-3.141592653589" upper="3.141592653589" velocity="3.2"/>
    <safety_controller k_position="100" k_velocity="10" soft_lower_limit="-3.132866007329" soft_upper_limit="3.132866007329"/>
  </joint>
  <link name="link5">
    <inertial>
      <origin rpy="0 0 0" xyz="1.2952E-06 -0.043824 0.0021728"/>
      <mass value="1.1683"/>
      <inertia ixx="0" ixy="0" ixz="0" iyy="0" iyz="0" izz="0"/>
    </inertial>
    <visual>
      <origin rpy="0 0 0" xyz="0 0 0"/>
      <geometry>
        <mesh filename="package://hsr_description/meshes/co602a/link5.STL"/>
      </geometry>
      <material name="">
        <color rgba="0.113 0.5098 0.7 1"/>
      </material>
    </visual>
    <collision>
      <origin rpy="0 0 0" xyz="0 0 0"/>
      <geometry>
        <mesh filename="package://hsr_description/meshes/co602a/link5.STL"/>
      </geometry>
    </collision>
  </link>
  <joint name="joint_5" type="revolute">
    <origin rpy="-1.5708 1.8044E-17 1.5708" xyz="0 0 0.39901"/>
    <parent link="link4"/>
    <child link="link5"/>
    <axis xyz="0 0 1"/>
    <limit effort="28" lower="-2.268928027592" upper="2.268928027592" velocity="3.2"/>
    <safety_controller k_position="100" k_velocity="10" soft_lower_limit="-2.260201381332" soft_upper_limit="2.260201381332"/>
  </joint>
  <link name="link6">
    <inertial>
      <origin rpy="0 0 0" xyz="-3.5784E-05 3.8806E-05 -0.025197"/>
      <mass value="0.20458"/>
      <inertia ixx="0" ixy="0" ixz="0" iyy="0" iyz="0" izz="0"/>
    </inertial>
    <visual>
      <origin rpy="0 0 0" xyz="0 0 0"/>
      <geometry>
        <mesh filename="package://hsr_description/meshes/co602a/link6.STL"/>
      </geometry>
      <material name="">
        <color rgba="0.113 0.5098 0.7 1"/>
      </material>
    </visual>
    <collision>
      <origin rpy="0 0 0" xyz="0 0 0"/>
      <geometry>
        <mesh filename="package://hsr_description/meshes/co602a/link6.STL"/>
      </geometry>
    </collision>
  </link>
  <joint name="joint_6" type="revolute">
    <origin rpy="-1.5708 1.0064E-16 -3.1416" xyz="0 -0.19849 0"/>
    <parent link="link5"/>
    <child link="link6"/>
    <axis xyz="0 0 1"/>
    <limit effort="28" lower="-6.283185307179" upper="6.283185307179" velocity="3.2"/>
    <safety_controller k_position="100" k_velocity="10" soft_lower_limit="-6.274458660919" soft_upper_limit="6.274458660919"/>
  </joint>
  <gazebo>
    <plugin filename="libgazebo_ros_control.so" name="gazebo_ros_control">
      <robotNamespace>/</robotNamespace>
      <robotSimType>gazebo_ros_control/DefaultRobotHWSim</robotSimType>
    </plugin>
  </gazebo>
  <transmission name="tran1">
    <type>transmission_interface/SimpleTransmission</type>
    <joint name="joint_1">
      <hardwareInterface>PositionJointInterface</hardwareInterface>
    </joint>
    <actuator name="motor1">
      <hardwareInterface>PositionJointInterface</hardwareInterface>
      <mechanicalReduction>1</mechanicalReduction>
    </actuator>
  </transmission>
  <transmission name="tran2">
    <type>transmission_interface/SimpleTransmission</type>
    <joint name="joint_2">
      <hardwareInterface>PositionJointInterface</hardwareInterface>
    </joint>
    <actuator name="motor2">
      <hardwareInterface>PositionJointInterface</hardwareInterface>
      <mechanicalReduction>1</mechanicalReduction>
    </actuator>
  </transmission>
  <transmission name="tran3">
    <type>transmission_interface/SimpleTransmission</type>
    <joint name="joint_3">
      <hardwareInterface>PositionJointInterface</hardwareInterface>
    </joint>
    <actuator name="motor3">
      <hardwareInterface>PositionJointInterface</hardwareInterface>
      <mechanicalReduction>1</mechanicalReduction>
    </actuator>
  </transmission>
  <transmission name="tran4">
    <type>transmission_interface/SimpleTransmission</type>
    <joint name="joint_4">
      <hardwareInterface>PositionJointInterface</hardwareInterface>
    </joint>
    <actuator name="motor4">
      <hardwareInterface>PositionJointInterface</hardwareInterface>
      <mechanicalReduction>1</mechanicalReduction>
    </actuator>
  </transmission>
  <transmission name="tran5">
    <type>transmission_interface/SimpleTransmission</type>
    <joint name="joint_5">
      <hardwareInterface>PositionJointInterface</hardwareInterface>
    </joint>
    <actuator name="motor5">
      <hardwareInterface>PositionJointInterface</hardwareInterface>
      <mechanicalReduction>1</mechanicalReduction>
    </actuator>
  </transmission>
  <transmission name="tran6">
    <type>transmission_interface/SimpleTransmission</type>
    <joint name="joint_6">
      <hardwareInterface>PositionJointInterface</hardwareInterface>
    </joint>
    <actuator name="motor6">
      <hardwareInterface>PositionJointInterface</hardwareInterface>
      <mechanicalReduction>1</mechanicalReduction>
    </actuator>
  </transmission>
  <!-- Size of square 'camera' box -->
  <link name="camera_link">
    <collision>
      <origin rpy="0 0 0" xyz="0 0 0"/>
      <geometry>
        <box size="0.05 0.05 0.05"/>
      </geometry>
    </collision>
    <visual>
      <origin rpy="0 0 0" xyz="0 0 0"/>
      <geometry>
        <box size="0.05 0.05 0.05"/>
      </geometry>
      <material name="red"/>
    </visual>
    <inertial>
      <mass value="1e-5"/>
      <origin rpy="0 0 0" xyz="0 0 0"/>
      <inertia ixx="1e-6" ixy="0" ixz="0" iyy="1e-6" iyz="0" izz="1e-6"/>
    </inertial>
  </link>
  <!-- kinect -->
  <gazebo reference="camera_link">
    <sensor name="openni_camera_camera" type="depth">
      <always_on>1</always_on>
      <visualize>true</visualize>
      <camera>
        <horizontal_fov>1.047</horizontal_fov>
        <image>
          <width>640</width>
          <height>480</height>
          <format>B8G8R8</format>
        </image>
        <depth_camera>

            </depth_camera>
        <clip>
          <near>0.1</near>
          <far>100</far>
        </clip>
      </camera>
      <plugin filename="libgazebo_ros_openni_kinect.so" name="camera_controller">
        <alwaysOn>true</alwaysOn>
        <baseline>0.2</baseline>
        <updateRate>30</updateRate>
        <cameraName>camera</cameraName>
        <frameName>kinect_frame</frameName>
        <imageTopicName>rgb/image_raw</imageTopicName>
        <depthImageTopicName>depth/image_raw</depthImageTopicName>
        <pointCloudTopicName>depth/points</pointCloudTopicName>
        <cameraInfoTopicName>rgb/camera_info</cameraInfoTopicName>
        <depthImageCameraInfoTopicName>depth/camera_info</depthImageCameraInfoTopicName>
        <pointCloudCutoff>0.5</pointCloudCutoff>
        <distortionK1>0</distortionK1>
        <distortionK2>0</distortionK2>
        <distortionK3>0</distortionK3>
        <distortionT1>0</distortionT1>
        <distortionT2>0</distortionT2>
        <CxPrime>0.0</CxPrime>
        <Cx>0.0</Cx>
        <Cy>0.0</Cy>
        <focalLength>0.0</focalLength>
      </plugin>
    </sensor>
  </gazebo>
  <link name="palm_base_link">
    <inertial>
      <origin rpy="0 0 0" xyz="-5.4686E-05 -0.0013298 0.029184"/>
      <mass value="0.19179"/>
      <inertia ixx="9.0598E-05" ixy="-5.0756E-07" ixz="-1.0778E-07" iyy="5.8619E-05" iyz="-1.0539E-05" izz="3.2071E-05"/>
    </inertial>
    <visual>
      <origin rpy="0 0 0" xyz="0 0 0"/>
      <geometry>
        <mesh filename="package://five_fight_base_link/meshes/base_link.STL"/>
      </geometry>
      <material name="">
        <color rgba="0.86667 0.86667 0.8902 1"/>
      </material>
    </visual>
    <collision>
      <origin rpy="0 0 0" xyz="0 0 0"/>
      <geometry>
        <mesh filename="package://five_fight_base_link/meshes/base_link.STL"/>
      </geometry>
    </collision>
  </link>
  <link name="Right_Link111">
    <inertial>
      <origin rpy="0 0 0" xyz="0.0284046972660885 -0.00981060404810299 0.0222000386975785"/>
      <mass value="0.22621959250221"/>
      <inertia ixx="0.000161057742168925" ixy="-3.93039257205975E-06" ixz="-2.59552833985103E-06" iyy="0.000358621491446785" iyz="4.70540238948447E-06" izz="0.000257940666810454"/>
    </inertial>
    <visual>
      <origin rpy="0 0 0" xyz="0 0 0"/>
      <geometry>
        <mesh filename="package://five_fight_right/meshes/Right_Link111.STL"/>
      </geometry>
      <material name="">
        <color rgba="0.827450980392157 0.83921568627451 0.827450980392157 1"/>
      </material>
    </visual>
    <collision>
      <origin rpy="0 0 0" xyz="0 0 0"/>
      <geometry>
        <mesh filename="package://five_fight_right/meshes/Right_Link111.STL"/>
      </geometry>
    </collision>
  </link>
  <link name="Right_Link1">
    <inertial>
      <origin rpy="0 0 0" xyz="0.0107729817589723 0.00213781834563882 -1.34009238303423E-07"/>
      <mass value="0.00330620599604871"/>
      <inertia ixx="1.55837657646135E-07" ixy="-3.78958094877833E-08" ixz="-5.07264353075226E-12" iyy="5.30383928507338E-07" iyz="-1.43523102869642E-12" izz="5.55164105212297E-07"/>
    </inertial>
    <visual>
      <origin rpy="0 0 0" xyz="0 0 0"/>
      <geometry>
        <mesh filename="package://five_fight_right/meshes/Right_Link1.STL"/>
      </geometry>
      <material name="">
        <color rgba="0.792156862745098 0.819607843137255 0.933333333333333 1"/>
      </material>
    </visual>
    <collision>
      <origin rpy="0 0 0" xyz="0 0 0"/>
      <geometry>
        <mesh filename="package://five_fight_right/meshes/Right_Link1.STL"/>
      </geometry>
    </collision>
  </link>
  <joint name="Right_Joint1" type="revolute">
    <origin rpy="5.2178E-10 -6.245E-17 -0.14966" xyz="0.08225 -0.0077547 -0.0040172"/>
    <parent link="Right_Link111"/>
    <child link="Right_Link1"/>
    <axis xyz="0 0 1"/>
    <limit effort="1" lower="-1.6" upper="0" velocity="1"/>
  </joint>
  <link name="Right_Link11">
    <inertial>
      <origin rpy="0 0 0" xyz="0.019017916514892 0.00563447754295066 1.90796464460963E-08"/>
      <mass value="0.00453366822308025"/>
      <inertia ixx="8.56969764665792E-08" ixy="-3.65502775787085E-08" ixz="2.02841411241907E-12" iyy="7.58232170757561E-07" iyz="6.07603435089188E-13" izz="7.68830975890361E-07"/>
    </inertial>
    <visual>
      <origin rpy="0 0 0" xyz="0 0 0"/>
      <geometry>
        <mesh filename="package://five_fight_right/meshes/Right_Link11.STL"/>
      </geometry>
      <material name="">
        <color rgba="1 1 1 1"/>
      </material>
    </visual>
    <collision>
      <origin rpy="0 0 0" xyz="0 0 0"/>
      <geometry>
        <mesh filename="package://five_fight_right/meshes/Right_Link11.STL"/>
      </geometry>
    </collision>
  </link>
  <joint name="Right_Joint11" type="revolute">
    <origin rpy="-5.086E-10 -1.1653E-10 -0.22524" xyz="0.032132 0 0"/>
    <parent link="Right_Link1"/>
    <child link="Right_Link11"/>
    <axis xyz="0 0 1"/>
    <limit effort="1" lower="-1.7" upper="0" velocity="1"/>
  </joint>
  <link name="Right_Link2">
    <inertial>
      <origin rpy="0 0 0" xyz="0.0107729781873397 0.00213783567195037 -1.14076048385314E-07"/>
      <mass value="0.00330621565435093"/>
      <inertia ixx="1.55837752420093E-07" ixy="-3.78955767951184E-08" ixz="-4.51740252002264E-12" iyy="5.30384784494186E-07" iyz="-1.08751322448059E-12" izz="5.55164342998361E-07"/>
    </inertial>
    <visual>
      <origin rpy="0 0 0" xyz="0 0 0"/>
      <geometry>
        <mesh filename="package://five_fight_right/meshes/Right_Link2.STL"/>
      </geometry>
      <material name="">
        <color rgba="0.792156862745098 0.819607843137255 0.933333333333333 1"/>
      </material>
    </visual>
    <collision>
      <origin rpy="0 0 0" xyz="0 0 0"/>
      <geometry>
        <mesh filename="package://five_fight_right/meshes/Right_Link2.STL"/>
      </geometry>
    </collision>
  </link>
  <joint name="Right_Joint2" type="revolute">
    <origin rpy="0.0056158 -0.034452 -0.16161" xyz="0.081939 -0.0077547 0.015305"/>
    <parent link="Right_Link111"/>
    <child link="Right_Link2"/>
    <axis xyz="0 0 1"/>
    <limit effort="1" lower="-1.6" upper="0" velocity="1"/>
  </joint>
  <link name="Right_Link22">
    <inertial>
      <origin rpy="0 0 0" xyz="0.0190179451505274 0.00563447968575673 1.97663586783137E-08"/>
      <mass value="0.00453367017295165"/>
      <inertia ixx="8.5696963969299E-08" ixy="-3.6550923619766E-08" ixz="1.59786933213099E-12" iyy="7.58233066456215E-07" iyz="6.81108952684927E-13" izz="7.68832070821997E-07"/>
    </inertial>
    <visual>
      <origin rpy="0 0 0" xyz="0 0 0"/>
      <geometry>
        <mesh filename="package://five_fight_right/meshes/Right_Link22.STL"/>
      </geometry>
      <material name="">
        <color rgba="1 1 1 1"/>
      </material>
    </visual>
    <collision>
      <origin rpy="0 0 0" xyz="0 0 0"/>
      <geometry>
        <mesh filename="package://five_fight_right/meshes/Right_Link22.STL"/>
      </geometry>
    </collision>
  </link>
  <joint name="Right_Joint22" type="revolute">
    <origin rpy="-5.0853E-10 -1.1686E-10 -0.22588" xyz="0.032132 0 0"/>
    <parent link="Right_Link2"/>
    <child link="Right_Link22"/>
    <axis xyz="0 0 1"/>
    <limit effort="1" lower="-1.7" upper="0" velocity="1"/>
  </joint>
  <link name="Right_Link3">
    <inertial>
      <origin rpy="0 0 0" xyz="0.0107730930654459 0.00213783260244832 -8.57328914740003E-08"/>
      <mass value="0.0033061482917439"/>
      <inertia ixx="1.55835970052989E-07" ixy="-3.78956285985318E-08" ixz="-3.98553229256186E-12" iyy="5.30379079243718E-07" iyz="-6.32137439938121E-13" izz="5.5516012983777E-07"/>
    </inertial>
    <visual>
      <origin rpy="0 0 0" xyz="0 0 0"/>
      <geometry>
        <mesh filename="package://five_fight_right/meshes/Right_Link3.STL"/>
      </geometry>
      <material name="">
        <color rgba="0.792156862745098 0.819607843137255 0.933333333333333 1"/>
      </material>
    </visual>
    <collision>
      <origin rpy="0 0 0" xyz="0 0 0"/>
      <geometry>
        <mesh filename="package://five_fight_right/meshes/Right_Link3.STL"/>
      </geometry>
    </collision>
  </link>
  <joint name="Right_Joint3" type="revolute">
    <origin rpy="0.010408 -0.086645 -0.11971" xyz="0.080765 -0.0077547 0.034505"/>
    <parent link="Right_Link111"/>
    <child link="Right_Link3"/>
    <axis xyz="0 0 1"/>
    <limit effort="1" lower="-1.6" upper="0" velocity="1"/>
  </joint>
  <link name="Right_Link33">
    <inertial>
      <origin rpy="0 0 0" xyz="0.01901789870244 0.00563447090562313 1.70050325960271E-08"/>
      <mass value="0.00453366652527048"/>
      <inertia ixx="8.56969335058099E-08" ixy="-3.65501984156752E-08" ixz="1.30339239962579E-12" iyy="7.58232117591424E-07" iyz="7.47249892192207E-13" izz="7.68830949295352E-07"/>
    </inertial>
    <visual>
      <origin rpy="0 0 0" xyz="0 0 0"/>
      <geometry>
        <mesh filename="package://five_fight_right/meshes/Right_Link33.STL"/>
      </geometry>
      <material name="">
        <color rgba="1 1 1 1"/>
      </material>
    </visual>
    <collision>
      <origin rpy="0 0 0" xyz="0 0 0"/>
      <geometry>
        <mesh filename="package://five_fight_right/meshes/Right_Link33.STL"/>
      </geometry>
    </collision>
  </link>
  <joint name="Right_Joint33" type="revolute">
    <origin rpy="-5.0314E-10 -1.3824E-10 -0.26815" xyz="0.032132 0 0"/>
    <parent link="Right_Link3"/>
    <child link="Right_Link33"/>
    <axis xyz="0 0 1"/>
    <limit effort="1" lower="-1.7" upper="0" velocity="1"/>
  </joint>
  <link name="Right_Link4">
    <inertial>
      <origin rpy="0 0 0" xyz="0.0107729931213964 0.00213782731321216 -7.95186542376647E-08"/>
      <mass value="0.00330620800050046"/>
      <inertia ixx="1.55837389573248E-07" ixy="-3.78958987950181E-08" ixz="-3.73884747536307E-12" iyy="5.30384597648764E-07" iyz="-3.63224479792676E-13" izz="5.55163794949727E-07"/>
    </inertial>
    <visual>
      <origin rpy="0 0 0" xyz="0 0 0"/>
      <geometry>
        <mesh filename="package://five_fight_right/meshes/Right_Link4.STL"/>
      </geometry>
      <material name="">
        <color rgba="0.792156862745098 0.819607843137255 0.933333333333333 1"/>
      </material>
    </visual>
    <collision>
      <origin rpy="0 0 0" xyz="0 0 0"/>
      <geometry>
        <mesh filename="package://five_fight_right/meshes/Right_Link4.STL"/>
      </geometry>
    </collision>
  </link>
  <joint name="Right_Joint4" type="revolute">
    <origin rpy="0.022524 -0.13781 -0.16255" xyz="0.078587 -0.0077547 0.053617"/>
    <parent link="Right_Link111"/>
    <child link="Right_Link4"/>
    <axis xyz="0 0 1"/>
    <limit effort="1" lower="-1.6" upper="0" velocity="1"/>
  </joint>
  <link name="Right_Link44">
    <inertial>
      <origin rpy="0 0 0" xyz="0.0155924853997512 0.00555619186912998 -1.21775195708468E-07"/>
      <mass value="0.00356886192445218"/>
      <inertia ixx="6.67767175628229E-08" ixy="-2.70385196277176E-08" ixz="-4.60032318294332E-12" iyy="4.33416353432936E-07" iyz="-1.36538016248102E-12" izz="4.39760949009649E-07"/>
    </inertial>
    <visual>
      <origin rpy="0 0 0" xyz="0 0 0"/>
      <geometry>
        <mesh filename="package://five_fight_right/meshes/Right_Link44.STL"/>
      </geometry>
      <material name="">
        <color rgba="1 1 1 1"/>
      </material>
    </visual>
    <collision>
      <origin rpy="0 0 0" xyz="0 0 0"/>
      <geometry>
        <mesh filename="package://five_fight_right/meshes/Right_Link44.STL"/>
      </geometry>
    </collision>
  </link>
  <joint name="Right_Joint44" type="revolute">
    <origin rpy="-5.0686E-10 -1.2389E-10 -0.23972" xyz="0.032132 0 0"/>
    <parent link="Right_Link4"/>
    <child link="Right_Link44"/>
    <axis xyz="0 0 1"/>
    <limit effort="1" lower="-1.7" upper="0" velocity="1"/>
  </joint>
  <link name="Right_Link5">
    <inertial>
      <origin rpy="0 0 0" xyz="-0.000668287872925624 -0.00209320996353089 0.0037633441647693"/>
      <mass value="0.00487390663164139"/>
      <inertia ixx="1.30408513803687E-07" ixy="-8.92030281859617E-09" ixz="-1.7660325194859E-08" iyy="1.70578986810531E-07" iyz="-1.02749399337787E-09" izz="2.1170907785655E-07"/>
    </inertial>
    <visual>
      <origin rpy="0 0 0" xyz="0 0 0"/>
      <geometry>
        <mesh filename="package://five_fight_right/meshes/Right_Link5.STL"/>
      </geometry>
      <material name="">
        <color rgba="0.827450980392157 0.83921568627451 0.827450980392157 1"/>
      </material>
    </visual>
    <collision>
      <origin rpy="0 0 0" xyz="0 0 0"/>
      <geometry>
        <mesh filename="package://five_fight_right/meshes/Right_Link5.STL"/>
      </geometry>
    </collision>
  </link>
  <joint name="Right_Joint5" type="revolute">
    <origin rpy="0.092365 1.1827 -1.4853" xyz="0.0089225 -0.022949 -0.00699"/>
    <parent link="Right_Link111"/>
    <child link="Right_Link5"/>
    <axis xyz="0 1 0"/>
    <limit effort="1" lower="-1" upper="0.3" velocity="1"/>
  </joint>
  <link name="Right_Link51">
    <inertial>
      <origin rpy="0 0 0" xyz="0.0261732090129406 0.00353701767650547 -1.92601341111875E-07"/>
      <mass value="0.00652729219675812"/>
      <inertia ixx="8.93817123585481E-07" ixy="6.28368840765271E-08" ixz="-2.00458419649248E-11" iyy="2.37370603240555E-06" iyz="-1.67466441559282E-12" izz="2.75021956933668E-06"/>
    </inertial>
    <visual>
      <origin rpy="0 0 0" xyz="0 0 0"/>
      <geometry>
        <mesh filename="package://five_fight_right/meshes/Right_Link51.STL"/>
      </geometry>
      <material name="">
        <color rgba="0.792156862745098 0.819607843137255 0.933333333333333 1"/>
      </material>
    </visual>
    <collision>
      <origin rpy="0 0 0" xyz="0 0 0"/>
      <geometry>
        <mesh filename="package://five_fight_right/meshes/Right_Link51.STL"/>
      </geometry>
    </collision>
  </link>
  <joint name="Right_Joint51" type="revolute">
    <origin rpy="3.1416 -5.2736E-16 0.96726" xyz="0.0065 -0.0035 0.00425"/>
    <parent link="Right_Link5"/>
    <child link="Right_Link51"/>
    <axis xyz="0 0 -1"/>
    <limit effort="1" lower="0" upper="0.4" velocity="1"/>
  </joint>
  <link name="Right_Link52">
    <inertial>
      <origin rpy="0 0 0" xyz="-0.007316119869056 -0.00552223433089214 2.14610152510231E-07"/>
      <mass value="0.0022695308360543"/>
      <inertia ixx="1.7281059843115E-07" ixy="4.52282139518593E-08" ixz="-2.88816078436063E-12" iyy="2.78046552011382E-07" iyz="7.05843881266438E-13" izz="2.99630657437474E-07"/>
    </inertial>
    <visual>
      <origin rpy="0 0 0" xyz="0 0 0"/>
      <geometry>
        <mesh filename="package://five_fight_right/meshes/Right_Link52.STL"/>
      </geometry>
      <material name="">
        <color rgba="0.827450980392157 0.83921568627451 0.827450980392157 1"/>
      </material>
    </visual>
    <collision>
      <origin rpy="0 0 0" xyz="0 0 0"/>
      <geometry>
        <mesh filename="package://five_fight_right/meshes/Right_Link52.STL"/>
      </geometry>
    </collision>
  </link>
  <joint name="Right_Joint52" type="revolute">
    <origin rpy="0 -1.3878E-16 2.9661" xyz="0.056001 0 0"/>
    <parent link="Right_Link51"/>
    <child link="Right_Link52"/>
    <axis xyz="0 0 1"/>
    <limit effort="1" lower="-0.4" upper="0" velocity="1"/>
  </joint>
  <link name="Right_Link53">
    <inertial>
      <origin rpy="0 0 0" xyz="-3.3937612879259E-06 0.0106230303829815 0.000584861433263272"/>
      <mass value="0.00330869751403717"/>
      <inertia ixx="1.96169236089202E-07" ixy="-1.43223823727531E-10" ixz="5.64113109591019E-11" iyy="8.67914197835909E-08" iyz="2.46315104630635E-08" izz="1.85481756939709E-07"/>
    </inertial>
    <visual>
      <origin rpy="0 0 0" xyz="0 0 0"/>
      <geometry>
        <mesh filename="package://five_fight_right/meshes/Right_Link53.STL"/>
      </geometry>
      <material name="">
        <color rgba="0.827450980392157 0.83921568627451 0.827450980392157 1"/>
      </material>
    </visual>
    <collision>
      <origin rpy="0 0 0" xyz="0 0 0"/>
      <geometry>
        <mesh filename="package://five_fight_right/meshes/Right_Link53.STL"/>
      </geometry>
    </collision>
  </link>
  <joint name="Right_Joint53" type="revolute">
    <origin rpy="1.7291 -1.5708 0" xyz="-0.022653 0 0"/>
    <parent link="Right_Link52"/>
    <child link="Right_Link53"/>
    <axis xyz="1 0 0"/>
    <limit effort="1" lower="-1" upper="0" velocity="1"/>
  </joint>
  <joint name="base_link_Right_Link111_joint" type="fixed">
    <origin rpy="0 -1.538096 1.57" xyz="-0.0092655 0.01809025 0.1079"/>
    <parent link="palm_base_link"/>
    <child link="Right_Link111"/>
    <axis xyz="0 0 0"/>
  </joint>
  <!-- <xacro:include filename="$(find hsr_description)/urdf/hsr_d435i.xacro.xml" /> -->
  <hsr_co602a/>
  <joint name="gripper_robot_joint" type="fixed">
    <parent link="link6"/>
    <child link="palm_base_link"/>
    <origin rpy="3.14 3.14 0" xyz="0.0 0.0 0.0"/>
  </joint>
  <joint name="kinect_base_link_joint" type="fixed">
    <origin rpy=" 0 0 0" xyz="-0.7 0 1.5"/>
    <parent link="base_link"/>
    <child link="camera_link"/>
  </joint>
  <link name="pick_point">
    <visual>
      <origin rpy="0 0 0" xyz="0 0 0"/>
      <geometry>
        <box size="0.001 0.0005 0.0005"/>
      </geometry>
    </visual>
  </link>
  <joint name="pick_point_joint" type="fixed">
    <origin rpy="3.152 -0.086645 -0.11971" xyz="0.080765 -0.0437547 0.034505"/>
    <parent link="Right_Link111"/>
    <child link="pick_point"/>
  </joint>
  <material name="aluminum">
    <color rgba="0.5 0.5 0.5 1"/>
  </material>
  <!-- camera body, with origin at bottom screw mount -->
  <joint name="camera_joint" type="fixed">
    <origin rpy="3.14 -1.57 1.57" xyz="0 0.033 0.071"/>
    <parent link="palm_base_link"/>
    <child link="camera_bottom_screw_frame"/>
  </joint>
  <link name="camera_bottom_screw_frame"/>
  <joint name="camera_link_joint" type="fixed">
    <origin rpy="0 0 0" xyz="0 0.0175 0.0125"/>
    <parent link="camera_bottom_screw_frame"/>
    <child link="d435_camera_link"/>
  </joint>
  <link name="d435_camera_link">
    <visual>
      <origin rpy="1.57079632679 0 1.57079632679" xyz="0.0149 -0.0175 0"/>
      <geometry>
        <!-- <box size="${d435_cam_width} ${d435_cam_height} ${d435_cam_depth}"/> -->
        <mesh filename="package://realsense2_description/meshes/d435.dae"/>
        <!--<mesh filename="package://realsense2_description/meshes/d435/d435.dae" />-->
      </geometry>
      <material name="aluminum"/>
    </visual>
    <collision>
      <origin rpy="0 0 0" xyz="0 -0.0175 0"/>
      <geometry>
        <box size="0.02505 0.09 0.025"/>
      </geometry>
    </collision>
    <inertial>
      <!-- The following are not reliable values, and should not be used for modeling -->
      <mass value="0.564"/>
      <origin xyz="0 0 0"/>
      <inertia ixx="0.003881243" ixy="0.0" ixz="0.0" iyy="0.000498940" iyz="0.0" izz="0.003879257"/>
    </inertial>
  </link>
  <!-- camera depth joints and links -->
  <joint name="camera_depth_joint" type="fixed">
    <origin rpy="0 0 0" xyz="0 0 0"/>
    <parent link="d435_camera_link"/>
    <child link="camera_depth_frame"/>
  </joint>
  <link name="camera_depth_frame"/>
  <joint name="camera_depth_optical_joint" type="fixed">
    <origin rpy="-1.57079632679 0 -1.57079632679" xyz="0 0 0"/>
    <parent link="camera_depth_frame"/>
    <child link="camera_depth_optical_frame"/>
  </joint>
  <link name="camera_depth_optical_frame"/>
  <!-- camera left IR joints and links -->
  <joint name="camera_left_ir_joint" type="fixed">
    <origin rpy="0 0 0" xyz="0 0.0 0"/>
    <parent link="camera_depth_frame"/>
    <child link="camera_left_ir_frame"/>
  </joint>
  <link name="camera_left_ir_frame"/>
  <joint name="camera_left_ir_optical_joint" type="fixed">
    <origin rpy="-1.57079632679 0 -1.57079632679" xyz="0 0 0"/>
    <parent link="camera_left_ir_frame"/>
    <child link="camera_left_ir_optical_frame"/>
  </joint>
  <link name="camera_left_ir_optical_frame"/>
  <!-- camera right IR joints and links -->
  <joint name="camera_right_ir_joint" type="fixed">
    <origin rpy="0 0 0" xyz="0 -0.05 0"/>
    <parent link="camera_depth_frame"/>
    <child link="camera_right_ir_frame"/>
  </joint>
  <link name="camera_right_ir_frame"/>
  <joint name="camera_right_ir_optical_joint" type="fixed">
    <origin rpy="-1.57079632679 0 -1.57079632679" xyz="0 0 0"/>
    <parent link="camera_right_ir_frame"/>
    <child link="camera_right_ir_optical_frame"/>
  </joint>
  <link name="camera_right_ir_optical_frame"/>
  <!-- camera color joints and links -->
  <joint name="camera_color_joint" type="fixed">
    <origin rpy="0 0 0" xyz="0 0.015 0"/>
    <parent link="camera_depth_frame"/>
    <child link="camera_color_frame"/>
  </joint>
  <link name="camera_color_frame"/>
  <joint name="camera_color_optical_joint" type="fixed">
    <origin rpy="-1.57079632679 0 -1.57079632679" xyz="0 0 0"/>
    <parent link="camera_color_frame"/>
    <child link="camera_color_optical_frame"/>
  </joint>
  <link name="camera_color_optical_frame"/>
</robot>

