<robot
  name="hsr_br609">

  <link name="world"/>

  <joint name="fixed" type="fixed">
    <parent link="world"/>
    <child link="base_link"/>
  </joint>

  <link
    name="base_link">
    <inertial>
      <origin
        xyz="-0.04048 0.13581 3.3868E-08"
        rpy="0 0 0" />
      <mass
        value="10.953" />
      <inertia
        ixx="0.093854"
        ixy="-0.0058279"
        ixz="-2.7968E-06"
        iyy="0.08053"
        iyz="-3.1346E-08"
        izz="0.12746" />
    </inertial>
    <visual>
      <origin
        xyz="0 0 0"
        rpy="0 0 0" />
      <geometry>
        <mesh
          filename="package://hsr_description/meshes/br609/606.STL" />
      </geometry>
      <material
        name="">
        <color
          rgba="1 1 1 1" />
      </material>
    </visual>
    <collision>
      <origin
        xyz="0 0 0"
        rpy="0 0 0" />
      <geometry>
        <mesh
          filename="package://hsr_description/meshes/br609/606.STL" />
      </geometry>
    </collision>
  </link>
  <link
    name="link1">
    <inertial>
      <origin
        xyz="-0.0163306206762966 -0.10203089300622 0.000232319908487642"
        rpy="0 0 0" />
      <mass
        value="4.59274863839256" />
      <inertia
        ixx="0.0270630197712814"
        ixy="-0.0033137935663697"
        ixz="-1.75074015007323E-05"
        iyy="0.0249050350102758"
        iyz="-9.30238114540491E-05"
        izz="0.0311201092025717" />
    </inertial>
    <visual>
      <origin
        xyz="0 0 0"
        rpy="0 0 0" />
      <geometry>
        <mesh
          filename="package://hsr_description/meshes/br609/link1.STL" />
      </geometry>
      <material
        name="">
        <color
          rgba="1 1 1 1" />
      </material>
    </visual>
    <collision>
      <origin
        xyz="0 0 0"
        rpy="0 0 0" />
      <geometry>
        <mesh
          filename="package://hsr_description/meshes/br609/link1.STL" />
      </geometry>
    </collision>
  </link>
  <joint
    name="joint_1"
    type="revolute">
    <origin
      xyz="0 0 0.2755"
      rpy="-1.5708 -6.123E-17 -1.5708" />
    <parent
      link="base_link" />
    <child
      link="link1" />
    <axis
      xyz="0 -1 0" />
    <limit  lower="-2.71415" upper="2.71415" effort="28.0" velocity="3.2"/>
    <safety_controller k_position="100"
                     k_velocity="10"
                     soft_lower_limit="-2.6179"
                     soft_upper_limit="2.6179" /> 
  </joint>
  <link
    name="link2">
    <inertial>
      <origin
        xyz="-0.343383970607949 0.000104694939987791 -0.0904888462359027"
        rpy="0 0 0" />
      <mass
        value="5.90673615464513" />
      <inertia
        ixx="0.0123417757465994"
        ixy="0.000172612377849355"
        ixz="0.00537221082086388"
        iyy="0.268650546344178"
        iyz="-4.58606980168505E-05"
        izz="0.26660968982124" />
    </inertial>
    <visual>
      <origin
        xyz="0 0 0"
        rpy="0 0 0" />
      <geometry>
        <mesh
          filename="package://hsr_description/meshes/br609/link2.STL" />
      </geometry>
      <material
        name="">
        <color
          rgba="1 1 1 1" />
      </material>
    </visual>
    <collision>
      <origin
        xyz="0 0 0"
        rpy="0 0 0" />
      <geometry>
        <mesh
          filename="package://hsr_description/meshes/br609/link2.STL" />
      </geometry>
    </collision>
  </link>
  <joint
    name="joint_2"
    type="revolute">
    <origin
      xyz="0 -0.145 0"
      rpy="-1.5707963267949 -1.22460635382238E-16 1.5707963267949" />
    <parent
      link="link1" />
    <child
      link="link2" />
    <axis
      xyz="0 0 -1" />
    <limit  lower="-3.1" upper="0" effort="28.0" velocity="3.2"/>
    <safety_controller k_position="100"
                     k_velocity="10"
                     soft_lower_limit="-3.1"
                     soft_upper_limit="0" /> 
  </joint>
  <link
    name="link3">
    <inertial>
      <origin
        xyz="0.00353711765158837 4.76840786842736E-05 0.0765655298267037"
        rpy="0 0 0" />
      <mass
        value="1.11115703458445" />
      <inertia
        ixx="0.00181208362757718"
        ixy="-8.11948339135492E-07"
        ixz="-8.10491987253363E-05"
        iyy="0.00341914947898713"
        iyz="2.44710124950598E-09"
        izz="0.00304059759788021" />
    </inertial>
    <visual>
      <origin
        xyz="0 0 0"
        rpy="0 0 0" />
      <geometry>
        <mesh
          filename="package://hsr_description/meshes/br609/link3.STL" />
      </geometry>
      <material
        name="">
        <color
          rgba="1 1 1 1" />
      </material>
    </visual>
    <collision>
      <origin
        xyz="0 0 0"
        rpy="0 0 0" />
      <geometry>
        <mesh
          filename="package://hsr_description/meshes/br609/link3.STL" />
      </geometry>
    </collision>
  </link>
  <joint
    name="joint_3"
    type="revolute">
    <origin
      xyz="-0.625999999928 0 -0.13649874600638"
      rpy="3.14159265358979 -5.665498452323E-16 -1.5707963267949" />
    <parent
      link="link2" />
    <child
      link="link3" />
    <axis
      xyz="0 0 1" />
    <limit  lower="-0.63" upper="3.4" effort="28.0" velocity="3.2"/>
    <safety_controller k_position="100"
                     k_velocity="10"
                     soft_lower_limit="-0.5585"
                     soft_upper_limit="3.4" /> 
  </joint>
  <link
    name="link4">
    <inertial>
      <origin
        xyz="0.00258987084780571 -7.84125502306665E-07 -0.252005454356107"
        rpy="0 0 0" />
      <mass
        value="2.67522980678295" />
      <inertia
        ixx="0.058522232482958"
        ixy="1.50767495468843E-09"
        ixz="0.00146600478334339"
        iyy="0.0585343344711802"
        iyz="7.12530843053089E-07"
        izz="0.00254492829516241" />
    </inertial>
    <visual>
      <origin
        xyz="0 0 0"
        rpy="0 0 0" />
      <geometry>
        <mesh
          filename="package://hsr_description/meshes/br609/link4.STL" />
      </geometry>
      <material
        name="">
        <color
          rgba="1 1 1 1" />
      </material>
    </visual>
    <collision>
      <origin
        xyz="0 0 0"
        rpy="0 0 0" />
      <geometry>
        <mesh
          filename="package://hsr_description/meshes/br609/link4.STL" />
      </geometry>
    </collision>
  </link>
  <joint
    name="joint_4"
    type="revolute">
    <origin
      xyz="0.0715000000000143 0 0.0860012539936202"
      rpy="3.14159265358979 1.5707963267949 0" />
    <parent
      link="link3" />
    <child
      link="link4" />
    <axis
      xyz="0 0 -1" />
    <limit  lower="-1.57" upper="1.57" effort="28.0" velocity="3.2"/>
    <safety_controller k_position="100"
                     k_velocity="10"
                     soft_lower_limit="-1.57"
                     soft_upper_limit="1.57" /> 
  </joint>
  <link
    name="link5">
    <inertial>
      <origin
        xyz="0.0464330051504287 1.32855309044055E-05 0.0215013015617751"
        rpy="0 0 0" />
      <mass
        value="0.867826372031057" />
      <inertia
        ixx="0.00215539648033595"
        ixy="-6.83725451098201E-09"
        ixz="-1.86245394764079E-05"
        iyy="0.00196841508516197"
        iyz="-6.44415649813966E-07"
        izz="0.000808751389178827" />
    </inertial>
    <visual>
      <origin
        xyz="0 0 0"
        rpy="0 0 0" />
      <geometry>
        <mesh
          filename="package://hsr_description/meshes/br609/link5.STL" />
      </geometry>
      <material
        name="">
        <color
          rgba="1 1 1 1" />
      </material>
    </visual>
    <collision>
      <origin
        xyz="0 0 0"
        rpy="0 0 0" />
      <geometry>
        <mesh
          filename="package://hsr_description/meshes/br609/link5.STL" />
      </geometry>
    </collision>
  </link>
  <joint
    name="joint_5"
    type="revolute">
    <origin
      xyz="0.0434999999994695 0 -0.459000000267993"
      rpy="-1.5707963267949 0 0" />
    <parent
      link="link4" />
    <child
      link="link5" />
    <axis
      xyz="-1 0 0" />
    <limit  lower="-1.68" upper="1.68" effort="28.0" velocity="3.2"/>
    <safety_controller k_position="100"
                     k_velocity="10"
                     soft_lower_limit="-1.68"
                     soft_upper_limit="1.68" /> 
  </joint>
  <link
    name="link6">
    <inertial>
      <origin
        xyz="-8.6588206334226E-05 8.65882063357803E-05 -0.0107649485573806"
        rpy="0 0 0" />
      <mass
        value="0.0270769176758969" />
      <inertia
        ixx="5.43734063425383E-06"
        ixy="-1.00108295441334E-07"
        ixz="4.39894702309314E-09"
        iyy="5.4373406342541E-06"
        iyz="-4.39894702336087E-09"
        izz="1.01791524117616E-05" />
    </inertial>
    <visual>
      <origin
        xyz="0 0 0"
        rpy="0 0 0" />
      <geometry>
        <mesh
          filename="package://hsr_description/meshes/br609/link6.STL" />
      </geometry>
      <material
        name="">
        <color
          rgba="1 1 1 1" />
      </material>
    </visual>
    <collision>
      <origin
        xyz="0 0 0"
        rpy="0 0 0" />
      <geometry>
        <mesh
          filename="package://hsr_description/meshes/br609/link6.STL" />
      </geometry>
    </collision>
  </link>
  <joint
    name="joint_6"
    type="revolute">
    <origin
      xyz="0.0474999999995303 0 0.104999999999948"
      rpy="3.14159265358979 0 1.5707963267949" />
    <parent
      link="link5" />
    <child
      link="link6" />
    <axis
      xyz="0 0 1" />
    <limit  lower="-4.5" upper="4.5" effort="28.0" velocity="3.2"/>
    <safety_controller k_position="100"
                     k_velocity="10"
                     soft_lower_limit="-4.5"
                     soft_upper_limit="4.5" /> 
  </joint>


<gazebo>
    <plugin name="gazebo_ros_control" filename="libgazebo_ros_control.so">
      <robotNamespace>/</robotNamespace>
      <robotSimType>gazebo_ros_control/DefaultRobotHWSim</robotSimType>
    </plugin>
  </gazebo>

  <transmission name="tran1">
    <type>transmission_interface/SimpleTransmission</type>
    <joint name="joint_1">
      <hardwareInterface>PositionJointInterface</hardwareInterface>
    </joint>
    <actuator name="motor1">
      <hardwareInterface>PositionJointInterface</hardwareInterface>
      <mechanicalReduction>1</mechanicalReduction>
    </actuator>
  </transmission>

  <transmission name="tran2">
    <type>transmission_interface/SimpleTransmission</type>
    <joint name="joint_2">
      <hardwareInterface>PositionJointInterface</hardwareInterface>
    </joint>
    <actuator name="motor2">
      <hardwareInterface>PositionJointInterface</hardwareInterface>
      <mechanicalReduction>1</mechanicalReduction>
    </actuator>
  </transmission>

  <transmission name="tran3">
    <type>transmission_interface/SimpleTransmission</type>
    <joint name="joint_3">
      <hardwareInterface>PositionJointInterface</hardwareInterface>
    </joint>
    <actuator name="motor3">
      <hardwareInterface>PositionJointInterface</hardwareInterface>
      <mechanicalReduction>1</mechanicalReduction>
    </actuator>
  </transmission>

  <transmission name="tran4">
    <type>transmission_interface/SimpleTransmission</type>
    <joint name="joint_4">
      <hardwareInterface>PositionJointInterface</hardwareInterface>
    </joint>
    <actuator name="motor4">
      <hardwareInterface>PositionJointInterface</hardwareInterface>
      <mechanicalReduction>1</mechanicalReduction>
    </actuator>
  </transmission>

  <transmission name="tran5">
    <type>transmission_interface/SimpleTransmission</type>
    <joint name="joint_5">
      <hardwareInterface>PositionJointInterface</hardwareInterface>
    </joint>
    <actuator name="motor5">
      <hardwareInterface>PositionJointInterface</hardwareInterface>
      <mechanicalReduction>1</mechanicalReduction>
    </actuator>
  </transmission>

  <transmission name="tran6">
    <type>transmission_interface/SimpleTransmission</type>
    <joint name="joint_6">
      <hardwareInterface>PositionJointInterface</hardwareInterface>
    </joint>
    <actuator name="motor6">
      <hardwareInterface>PositionJointInterface</hardwareInterface>
      <mechanicalReduction>1</mechanicalReduction>
    </actuator>
  </transmission>

</robot>
