<robot
  name="hsr_br609">

  <link name="world"/>

  <joint name="fixed" type="fixed">
    <parent link="world"/>
    <child link="base_link"/>
	<origin
      xyz="0 0 1"
      rpy="0 0 0" />
  </joint>

  <link
    name="base_link">
    <inertial>
      <origin
        xyz="-0.040482 1.0116E-08 -0.28469"
        rpy="0 0 0" />
      <mass
        value="10.954" />
      <inertia
        ixx="3.5635E-06"
        ixy="-1.1697E-13"
        ixz="-1.3864E-06"
        iyy="3.5485E-06"
        iyz="-2.1688E-13"
        izz="1.9716E-06" />
    </inertial>
    <visual>
      <origin
        xyz="0 0 0"
        rpy="0 0 0" />
      <geometry>
        <mesh
          filename="package://hsr_description/meshes/br609/base_link.STL" />
      </geometry>
      <material
        name="">
        <color
          rgba="0.1 0.1 0.1 1" />
      </material>
    </visual>
    <collision>
      <origin
        xyz="0 0 0"
        rpy="0 0 0" />
      <geometry>
        <mesh
          filename="package://hsr_description/meshes/br609/base_link.STL" />
      </geometry>
    </collision>
  </link>
  <link
    name="link1">
    <inertial>
      <origin
        xyz="-0.0012283 0.01616 -0.043389"
        rpy="0 0 0" />
      <mass
        value="4.6413" />
      <inertia
        ixx="0"
        ixy="0"
        ixz="0"
        iyy="0"
        iyz="0"
        izz="0" />
    </inertial>
    <visual>
      <origin
        xyz="0 0 0"
        rpy="0 0 0" />
      <geometry>
        <mesh
          filename="package://hsr_description/meshes/br609/link1.STL" />
      </geometry>
      <material
        name="">
        <color
          rgba="0.37 0.125 0.125 1" />
      </material>
    </visual>
    <collision>
      <origin
        xyz="0 0 0"
        rpy="0 0 0" />
      <geometry>
        <mesh
          filename="package://hsr_description/meshes/br609/link1.STL" />
      </geometry>
    </collision>
  </link>
  <joint
    name="joint_1"
    type="revolute">
    <origin
      xyz="0 0 0"
      rpy="0 0 0" />
    <parent
      link="base_link" />
    <child
      link="link1" />
    <axis
      xyz="0 0 1" />
    <limit  lower="-2.71415" upper="2.71415" effort="28.0" velocity="3.2"/>
  <safety_controller k_position="100"
                     k_velocity="10"
                     soft_lower_limit="-2.6179"
                     soft_upper_limit="2.6179" /> 
  </joint>
  <link
    name="link2">
    <inertial>
      <origin
        xyz="0.34314 -0.00011906 0.005961"
        rpy="0 0 0" />
      <mass
        value="5.9083" />
      <inertia
        ixx="0"
        ixy="0"
        ixz="0"
        iyy="0"
        iyz="0"
        izz="0" />
    </inertial>
    <visual>
      <origin
        xyz="0 0 0"
        rpy="0 0 0" />
      <geometry>
        <mesh
          filename="package://hsr_description/meshes/br609/link2.STL" />
      </geometry>
      <material
        name="">
        <color
          rgba="0.25098 0.25098 0.25098 1" />
      </material>
    </visual>
    <collision>
      <origin
        xyz="0 0 0"
        rpy="0 0 0" />
      <geometry>
        <mesh
          filename="package://hsr_description/meshes/br609/link2.STL" />
      </geometry>
    </collision>
  </link>
  <joint
    name="joint_2"
    type="revolute">
    <origin
      xyz="0 -0.0965 0"
      rpy="-1.5708 -3.3106E-34 2.6541E-17" />
    <parent
      link="link1" />
    <child
      link="link2" />
    <axis
      xyz="0 0 1" />
    <limit  lower="-3.1" upper="0" effort="28.0" velocity="3.2"/>
  <safety_controller k_position="100"
                     k_velocity="10"
                     soft_lower_limit="-3.1"
                     soft_upper_limit="0" /> 
  </joint>
  <link
    name="link3">
    <inertial>
      <origin
        xyz="-0.0035374 4.7672E-05 0.0094347"
        rpy="0 0 0" />
      <mass
        value="1.1112" />
      <inertia
        ixx="0"
        ixy="0"
        ixz="0"
        iyy="0"
        iyz="0"
        izz="0" />
    </inertial>
    <visual>
      <origin
        xyz="0 0 0"
        rpy="0 0 0" />
      <geometry>
        <mesh
          filename="package://hsr_description/meshes/br609/link3.STL" />
      </geometry>
      <material
        name="">
        <color
          rgba="0.37 0.125 0.125 1" />
      </material>
    </visual>
    <collision>
      <origin
        xyz="0 0 0"
        rpy="0 0 0" />
      <geometry>
        <mesh
          filename="package://hsr_description/meshes/br609/link3.STL" />
      </geometry>
    </collision>
  </link>
  <joint
    name="joint_3"
    type="revolute">
    <origin
      xyz="0.626 0 -0.126"
      rpy="2.4344E-17 -2.6448E-17 -1.5708" />
    <parent
      link="link2" />
    <child
      link="link3" />
    <axis
      xyz="0 0 1" />
    <limit  lower="-0.63" upper="3.4" effort="28.0" velocity="3.2"/>
  <safety_controller k_position="100"
                     k_velocity="10"
                     soft_lower_limit="-0.5585"
                     soft_upper_limit="3.4" /> 
  </joint>
  <link
    name="link4">
    <inertial>
      <origin
        xyz="0.0025895995966988 -5.32617778548072E-07 0.206998560343282"
        rpy="0 0 0" />
      <mass
        value="2.67517353862944" />
      <inertia
        ixx="0"
        ixy="0"
        ixz="0"
        iyy="0"
        iyz="0"
        izz="0" />
    </inertial>
    <visual>
      <origin
        xyz="0 0 0"
        rpy="0 0 0" />
      <geometry>
        <mesh
          filename="package://hsr_description/meshes/br609/link4.STL" />
      </geometry>
      <material
        name="">
        <color
          rgba="0.25098 0.25098 0.25098 1" />
      </material>
    </visual>
    <collision>
      <origin
        xyz="0 0 0"
        rpy="0 0 0" />
      <geometry>
        <mesh
          filename="package://hsr_description/meshes/br609/link4.STL" />
      </geometry>
    </collision>
  </link>
  <joint
    name="joint_4"
    type="revolute">
    <origin
      xyz="-0.5305 0 0"
      rpy="1.6474 1.5708 1.6474" />
    <parent
      link="link3" />
    <child
      link="link4" />
    <axis
      xyz="0 0 -1" />
    <limit  lower="-1.57" upper="1.57" effort="28.0" velocity="3.2"/>
  <safety_controller k_position="100"
                     k_velocity="10"
                     soft_lower_limit="-1.57"
                     soft_upper_limit="1.57" /> 
  </joint>
  <link
    name="link5">
    <inertial>
      <origin
        xyz="0.0215336507406799 -1.34252172634408E-05 -0.00106647846553021"
        rpy="0 0 0" />
      <mass
        value="0.868403298162055" />
      <inertia
        ixx="1.59172077755755E-07"
        ixy="-1.86970316998097E-10"
        ixz="-1.3172322054362E-08"
        iyy="7.5420853954828E-07"
        iyz="-2.35051937834349E-12"
        izz="7.55207186633509E-07" />
    </inertial>
    <visual>
      <origin
        xyz="0 0 0"
        rpy="0 0 0" />
      <geometry>
        <mesh
          filename="package://hsr_description/meshes/br609/link5.STL" />
      </geometry>
      <material
        name="">
        <color
          rgba="0.37 0.125 0.125 1" />
      </material>
    </visual>
    <collision>
      <origin
        xyz="0 0 0"
        rpy="0 0 0" />
      <geometry>
        <mesh
          filename="package://hsr_description/meshes/br609/link5.STL" />
      </geometry>
    </collision>
  </link>
  <joint
    name="joint_5"
    type="revolute">
    <origin
      xyz="0.091 0 0"
      rpy="0 1.5708 0" />
    <parent
      link="link4" />
    <child
      link="link5" />
    <axis
      xyz="0 0 -1" />
    <limit  lower="-1.68" upper="1.68" effort="28.0" velocity="3.2"/>
  <safety_controller k_position="100"
                     k_velocity="10"
                     soft_lower_limit="-1.68"
                     soft_upper_limit="1.68" /> 
  </joint>
  <link
    name="link6">
    <inertial>
      <origin
        xyz="-0.0062351 -0.00012245 -5.1514E-14"
        rpy="0 0 0" />
      <mass
        value="0.027077" />
      <inertia
        ixx="0"
        ixy="0"
        ixz="0"
        iyy="0"
        iyz="0"
        izz="0" />
    </inertial>
    <visual>
      <origin
        xyz="0 0 0"
        rpy="0 0 0" />
      <geometry>
        <mesh
          filename="package://hsr_description/meshes/br609/link6.STL" />
      </geometry>
      <material
        name="">
        <color
          rgba="0.1 0.1 0.1 1" />
      </material>
    </visual>
    <collision>
      <origin
        xyz="0 0 0"
        rpy="0 0 0" />
      <geometry>
        <mesh
          filename="package://hsr_description/meshes/br609/link6.STL" />
      </geometry>
    </collision>
  </link>
  <joint
    name="joint_6"
    type="revolute">
    <origin
      xyz="0.122 0 0"
      rpy="2.9386E-15 5.7152E-17 1.15E-16" />
    <parent
      link="link5" />
    <child
      link="link6" />
    <axis
      xyz="1 0 0" />
     <limit  lower="-4.5" upper="4.5" effort="28.0" velocity="3.2"/>
  <safety_controller k_position="100"
                     k_velocity="10"
                     soft_lower_limit="-4.5"
                     soft_upper_limit="4.5" /> 
  </joint>

<gazebo>
    <plugin name="gazebo_ros_control" filename="libgazebo_ros_control.so">
      <robotNamespace>/</robotNamespace>
      <robotSimType>gazebo_ros_control/DefaultRobotHWSim</robotSimType>
    </plugin>
  </gazebo>

<gazebo reference="base_link">
	<material>Gazebo/FlatBlack</material>
</gazebo>
<gazebo reference="link1">
	<material>Gazebo/Red</material>
</gazebo>
<gazebo reference="link2">
	<material>Gazebo/Grey</material>
</gazebo>
<gazebo reference="link3">
	<material>Gazebo/Red</material>
</gazebo>
<gazebo reference="link4">
	<material>Gazebo/Grey</material>
</gazebo>
<gazebo reference="link5">
	<material>Gazebo/Red</material>
</gazebo>
<gazebo reference="link6">
	<material>Gazebo/Black</material>
</gazebo>

  <transmission name="tran1">
    <type>transmission_interface/SimpleTransmission</type>
    <joint name="joint_1">
      <hardwareInterface>PositionJointInterface</hardwareInterface>
    </joint>
    <actuator name="motor1">
      <hardwareInterface>PositionJointInterface</hardwareInterface>
      <mechanicalReduction>1</mechanicalReduction>
    </actuator>
  </transmission>

  <transmission name="tran2">
    <type>transmission_interface/SimpleTransmission</type>
    <joint name="joint_2">
      <hardwareInterface>PositionJointInterface</hardwareInterface>
    </joint>
    <actuator name="motor2">
      <hardwareInterface>PositionJointInterface</hardwareInterface>
      <mechanicalReduction>1</mechanicalReduction>
    </actuator>
  </transmission>

  <transmission name="tran3">
    <type>transmission_interface/SimpleTransmission</type>
    <joint name="joint_3">
      <hardwareInterface>PositionJointInterface</hardwareInterface>
    </joint>
    <actuator name="motor3">
      <hardwareInterface>PositionJointInterface</hardwareInterface>
      <mechanicalReduction>1</mechanicalReduction>
    </actuator>
  </transmission>

  <transmission name="tran4">
    <type>transmission_interface/SimpleTransmission</type>
    <joint name="joint_4">
      <hardwareInterface>PositionJointInterface</hardwareInterface>
    </joint>
    <actuator name="motor4">
      <hardwareInterface>PositionJointInterface</hardwareInterface>
      <mechanicalReduction>1</mechanicalReduction>
    </actuator>
  </transmission>

  <transmission name="tran5">
    <type>transmission_interface/SimpleTransmission</type>
    <joint name="joint_5">
      <hardwareInterface>PositionJointInterface</hardwareInterface>
    </joint>
    <actuator name="motor5">
      <hardwareInterface>PositionJointInterface</hardwareInterface>
      <mechanicalReduction>1</mechanicalReduction>
    </actuator>
  </transmission>

  <transmission name="tran6">
    <type>transmission_interface/SimpleTransmission</type>
    <joint name="joint_6">
      <hardwareInterface>PositionJointInterface</hardwareInterface>
    </joint>
    <actuator name="motor6">
      <hardwareInterface>PositionJointInterface</hardwareInterface>
      <mechanicalReduction>1</mechanicalReduction>
    </actuator>
  </transmission>

</robot>
