<robot
  name="hsr_co602a">

  <link name="world"/>

  <joint name="fixed" type="fixed">
    <parent link="world"/>
    <child link="base_link"/>
	<origin
      xyz="0 0 1"
      rpy="0 0 0" />
  </joint> 
  
  <link
    name="base_link">
    <inertial>
      <origin
        xyz="-0.0024614 3.992E-07 0.076752"
        rpy="0 0 0" />
      <mass
        value="4.8818" />
      <inertia
        ixx="0.093861"
        ixy="-0.0058307"
        ixz="-2.7963E-06"
        iyy="0.080534"
        iyz="4.4333E-09"
        izz="0.12747" />
    </inertial>
    <visual>
      <origin
        xyz="0 0 0"
        rpy="0 0 0" />
      <geometry>
        <mesh
          filename="package://hsr_description/meshes/co602a/base_link.STL" />
      </geometry>
      <material
        name="">
        <color
          rgba="0.1137 0.5098 0.97 1" />
      </material>
    </visual>
    <collision>
      <origin
        xyz="0 0 0"
        rpy="0 0 0" />
      <geometry>
        <mesh
          filename="package://hsr_description/meshes/co602a/base_link.STL" />
      </geometry>
    </collision>
  </link>
  <link
    name="link1">
    <inertial>
      <origin
        xyz="-3.4523E-06 -0.02843 0.064536"
        rpy="0 0 0" />
      <mass
        value="4.9839" />
      <inertia
        ixx="0"
        ixy="0"
        ixz="0"
        iyy="0"
        iyz="0"
        izz="0" />
    </inertial>
    <visual>
      <origin
        xyz="0 0 0"
        rpy="0 0 0" />
      <geometry>
        <mesh
          filename="package://hsr_description/meshes/co602a/link1.STL" />
      </geometry>
      <material
        name="">
        <color
          rgba="0.1137 0.5098 0.97 1" />
      </material>
    </visual>
    <collision>
      <origin
        xyz="0 0 0"
        rpy="0 0 0" />
      <geometry>
        <mesh
          filename="package://hsr_description/meshes/co602a/link1.STL" />
      </geometry>
    </collision>
  </link>
  <joint
    name="joint_1"
    type="revolute">
    <origin
      xyz="0 0 0.352"
      rpy="3.1416 0 -3.4694E-18" />
    <parent
      link="base_link" />
    <child
      link="link1" />
    <axis
      xyz="0 0 -1" />
    <limit
      lower="-3.490658503988"
      upper="3.490658503988"
      effort="28"
      velocity="3.2" />
    <safety_controller
      soft_upper_limit="3.481931857728"
      soft_lower_limit="-3.481931857728"
      k_position="100"
      k_velocity="10" />
  </joint>
  <link
    name="link2">
    <inertial>
      <origin
        xyz="4.7574E-06 -0.18488 -0.037843"
        rpy="0 0 0" />
      <mass
        value="6.6939" />
      <inertia
        ixx="0"
        ixy="0"
        ixz="0"
        iyy="0"
        iyz="0"
        izz="0" />
    </inertial>
    <visual>
      <origin
        xyz="0 0 0"
        rpy="0 0 0" />
      <geometry>
        <mesh
          filename="package://hsr_description/meshes/co602a/link2.STL" />
      </geometry>
      <material
        name="">
        <color
          rgba="0.97 0.7 0 1" />
      </material>
    </visual>
    <collision>
      <origin
        xyz="0 0 0"
        rpy="0 0 0" />
      <geometry>
        <mesh
          filename="package://hsr_description/meshes/co602a/link2.STL" />
      </geometry>
    </collision>
  </link>
  <joint
    name="joint_2"
    type="revolute">
    <origin
      xyz="0 0 0"
      rpy="1.5708 -1.5708 0" />
    <parent
      link="link1" />
    <child
      link="link2" />
    <axis
      xyz="0 0 1" />
    <limit
      lower="-2.268928027592"
      upper="1"
      effort="28"
      velocity="3.2" />
    <safety_controller
      soft_upper_limit="1"
      soft_lower_limit="-2.260201381332"
      k_position="100"
      k_velocity="10" />
  </joint>
  <link
    name="link3">
    <inertial>
      <origin
        xyz="-4.098E-05 -0.085254 -0.035956"
        rpy="0 0 0" />
      <mass
        value="2.3223" />
      <inertia
        ixx="0"
        ixy="0"
        ixz="0"
        iyy="0"
        iyz="0"
        izz="0" />
    </inertial>
    <visual>
      <origin
        xyz="0 0 0"
        rpy="0 0 0" />
      <geometry>
        <mesh
          filename="package://hsr_description/meshes/co602a/link3.STL" />
      </geometry>
      <material
        name="">
        <color
          rgba="0.1137 0.5098 0.97 1" />
      </material>
    </visual>
    <collision>
      <origin
        xyz="0 0 0"
        rpy="0 0 0" />
      <geometry>
        <mesh
          filename="package://hsr_description/meshes/co602a/link3.STL" />
      </geometry>
    </collision>
  </link>
  <joint
    name="joint_3"
    type="revolute">
    <origin
      xyz="0 -0.4 0"
      rpy="6.3741E-17 1.5386E-16 -1.5708" />
    <parent
      link="link2" />
    <child
      link="link3" />
    <axis
      xyz="0 0 1" />
    <limit
      lower="1"
      upper="3.665191429188"
      effort="28"
      velocity="3.2" />
    <safety_controller
      soft_upper_limit="3.656464782928"
      soft_lower_limit="0.008726646259"
      k_position="100"
      k_velocity="10" />
  </joint>
  <link
    name="link4">
    <inertial>
      <origin
        xyz="0.049627 2.6934E-06 0.3246"
        rpy="0 0 0" />
      <mass
        value="1.3111" />
      <inertia
        ixx="0"
        ixy="0"
        ixz="0"
        iyy="0"
        iyz="0"
        izz="0" />
    </inertial>
    <visual>
      <origin
        xyz="0 0 0"
        rpy="0 0 0" />
      <geometry>
        <mesh
          filename="package://hsr_description/meshes/co602a/link4.STL" />
      </geometry>
      <material
        name="">
        <color
          rgba="0.97 0.7 0 1" />
      </material>
    </visual>
    <collision>
      <origin
        xyz="0 0 0"
        rpy="0 0 0" />
      <geometry>
        <mesh
          filename="package://hsr_description/meshes/co602a/link4.STL" />
      </geometry>
    </collision>
  </link>
  <joint
    name="joint_4"
    type="revolute">
    <origin
      xyz="0 0 0"
      rpy="1.5708 1.5708 0" />
    <parent
      link="link3" />
    <child
      link="link4" />
    <axis
      xyz="0 0 1" />
    <limit
      lower="-3.141592653589"
      upper="3.141592653589"
      effort="28"
      velocity="3.2" />
    <safety_controller
      soft_upper_limit="3.132866007329"
      soft_lower_limit="-3.132866007329"
      k_position="100"
      k_velocity="10" />
  </joint>
  <link
    name="link5">
    <inertial>
      <origin
        xyz="1.2952E-06 -0.043824 0.0021728"
        rpy="0 0 0" />
      <mass
        value="1.1683" />
      <inertia
        ixx="0"
        ixy="0"
        ixz="0"
        iyy="0"
        iyz="0"
        izz="0" />
    </inertial>
    <visual>
      <origin
        xyz="0 0 0"
        rpy="0 0 0" />
      <geometry>
        <mesh
          filename="package://hsr_description/meshes/co602a/link5.STL" />
      </geometry>
      <material
        name="">
        <color
          rgba="0.113 0.5098 0.7 1" />
      </material>
    </visual>
    <collision>
      <origin
        xyz="0 0 0"
        rpy="0 0 0" />
      <geometry>
        <mesh
          filename="package://hsr_description/meshes/co602a/link5.STL" />
      </geometry>
    </collision>
  </link>
  <joint
    name="joint_5"
    type="revolute">
    <origin
      xyz="0 0 0.39901"
      rpy="-1.5708 1.8044E-17 1.5708" />
    <parent
      link="link4" />
    <child
      link="link5" />
    <axis
      xyz="0 0 1" />
    <limit
      lower="-2.268928027592"
      upper="2.268928027592"
      effort="28"
      velocity="3.2" />
    <safety_controller
      soft_upper_limit="2.260201381332"
      soft_lower_limit="-2.260201381332"
      k_position="100"
      k_velocity="10" />
  </joint>
  <link
    name="link6">
    <inertial>
      <origin
        xyz="-3.5784E-05 3.8806E-05 -0.025197"
        rpy="0 0 0" />
      <mass
        value="0.20458" />
      <inertia
        ixx="0"
        ixy="0"
        ixz="0"
        iyy="0"
        iyz="0"
        izz="0" />
    </inertial>
    <visual>
      <origin
        xyz="0 0 0"
        rpy="0 0 0" />
      <geometry>
        <mesh
          filename="package://hsr_description/meshes/co602a/link6.STL" />
      </geometry>
      <material
        name="">
        <color
          rgba="0.113 0.5098 0.7 1" />
      </material>
    </visual>
    <collision>
      <origin
        xyz="0 0 0"
        rpy="0 0 0" />
      <geometry>
        <mesh
          filename="package://hsr_description/meshes/co602a/link6.STL" />
      </geometry>
    </collision>
  </link>
  <joint
    name="joint_6"
    type="revolute">
    <origin
      xyz="0 -0.19849 0"
      rpy="-1.5708 1.0064E-16 -3.1416" />
    <parent
      link="link5" />
    <child
      link="link6" />
    <axis
      xyz="0 0 1" />
    <limit
      lower="-6.283185307179"
      upper="6.283185307179"
      effort="28"
      velocity="3.2" />
    <safety_controller
      soft_upper_limit="6.274458660919"
      soft_lower_limit="-6.274458660919"
      k_position="100"
      k_velocity="10" />
  </joint>

<gazebo>
    <plugin name="gazebo_ros_control" filename="libgazebo_ros_control.so">
      <robotNamespace>/</robotNamespace>
      <robotSimType>gazebo_ros_control/DefaultRobotHWSim</robotSimType>
    </plugin>
  </gazebo>

  <transmission name="tran1">
    <type>transmission_interface/SimpleTransmission</type>
    <joint name="joint_1">
      <hardwareInterface>PositionJointInterface</hardwareInterface>
    </joint>
    <actuator name="motor1">
      <hardwareInterface>PositionJointInterface</hardwareInterface>
      <mechanicalReduction>1</mechanicalReduction>
    </actuator>
  </transmission>

  <transmission name="tran2">
    <type>transmission_interface/SimpleTransmission</type>
    <joint name="joint_2">
      <hardwareInterface>PositionJointInterface</hardwareInterface>
    </joint>
    <actuator name="motor2">
      <hardwareInterface>PositionJointInterface</hardwareInterface>
      <mechanicalReduction>1</mechanicalReduction>
    </actuator>
  </transmission>

  <transmission name="tran3">
    <type>transmission_interface/SimpleTransmission</type>
    <joint name="joint_3">
      <hardwareInterface>PositionJointInterface</hardwareInterface>
    </joint>
    <actuator name="motor3">
      <hardwareInterface>PositionJointInterface</hardwareInterface>
      <mechanicalReduction>1</mechanicalReduction>
    </actuator>
  </transmission>

  <transmission name="tran4">
    <type>transmission_interface/SimpleTransmission</type>
    <joint name="joint_4">
      <hardwareInterface>PositionJointInterface</hardwareInterface>
    </joint>
    <actuator name="motor4">
      <hardwareInterface>PositionJointInterface</hardwareInterface>
      <mechanicalReduction>1</mechanicalReduction>
    </actuator>
  </transmission>

  <transmission name="tran5">
    <type>transmission_interface/SimpleTransmission</type>
    <joint name="joint_5">
      <hardwareInterface>PositionJointInterface</hardwareInterface>
    </joint>
    <actuator name="motor5">
      <hardwareInterface>PositionJointInterface</hardwareInterface>
      <mechanicalReduction>1</mechanicalReduction>
    </actuator>
  </transmission>

  <transmission name="tran6">
    <type>transmission_interface/SimpleTransmission</type>
    <joint name="joint_6">
      <hardwareInterface>PositionJointInterface</hardwareInterface>
    </joint>
    <actuator name="motor6">
      <hardwareInterface>PositionJointInterface</hardwareInterface>
      <mechanicalReduction>1</mechanicalReduction>
    </actuator>
  </transmission>

</robot>
