<robot
  name="hsr_br606">

  <link name="world"/>

  <joint name="fixed" type="fixed">
    <parent link="world"/>
    <child link="base_link"/>
	<origin
      xyz="0 0 1"
      rpy="0 0 0" />
  </joint>

  <link
    name="base_link">
    <inertial>
      <origin
        xyz="-0.040482 0.13581 -9.8671E-09"
        rpy="0 0 0" />
      <mass
        value="10.954" />
      <inertia
        ixx="0.093861"
        ixy="-0.0058307"
        ixz="-2.7963E-06"
        iyy="0.080534"
        iyz="4.4333E-09"
        izz="0.12747" />
    </inertial>
    <visual>
      <origin
        xyz="0 0 0"
        rpy="0 0 0" />
      <geometry>
        <mesh
          filename="package://hsr_description/meshes/br606/base_link.STL" />
      </geometry>
      <material
        name="">
        <color
          rgba="0.752941176470588 0.752941176470588 0.752941176470588 1" />
      </material>
    </visual>
    <collision>
      <origin
        xyz="0 0 0"
        rpy="0 0 0" />
      <geometry>
        <mesh
          filename="package://hsr_description/meshes/br606/base_link.STL" />
      </geometry>
    </collision>
  </link>
  <link
    name="link1">
    <inertial>
      <origin
        xyz="-0.0163304681469045 -0.102030939733314 0.000232368620113542"
        rpy="0 0 0" />
      <mass
        value="4.59276430213053" />
      <inertia
        ixx="0.0270629615715191"
        ixy="-0.00331383168971066"
        ixz="-1.75303777414231E-05"
        iyy="0.0249050231994336"
        iyz="-9.30496066742349E-05"
        izz="0.0311200335574428" />
    </inertial>
    <visual>
      <origin
        xyz="0 0 0"
        rpy="0 0 0" />
      <geometry>
        <mesh
          filename="package://hsr_description/meshes/br606/link1.STL" />
      </geometry>
      <material
        name="">
        <color
          rgba="1 0 0 1" />
      </material>
    </visual>
    <collision>
      <origin
        xyz="0 0 0"
        rpy="0 0 0" />
      <geometry>
        <mesh
          filename="package://hsr_description/meshes/br606/link1.STL" />
      </geometry>
    </collision>
  </link>
  <joint
    name="joint_1"
    type="revolute">
    <origin
      xyz="0 0 0"
      rpy="-1.5707963267949 -1.5707963267949 0" />
    <parent
      link="base_link" />
    <child
      link="link1" />
    <axis
      xyz="1 0 0" />
    <limit  lower="-2.71415" upper="2.71415" effort="28.0" velocity="3.2"/>
  <safety_controller k_position="100"
                     k_velocity="10"
                     soft_lower_limit="-2.6179"
                     soft_upper_limit="2.6179" /> 
  </joint>
  <link
    name="link2">
    <inertial>
      <origin
        xyz="-0.394642177371542 0.000111323620801942 -0.0909848584504052"
        rpy="0 0 0" />
      <mass
        value="6.56009345873244" />
      <inertia
        ixx="0.0131883649088827"
        ixy="0.000223190726719286"
        ixz="0.0065397673191675"
        iyy="0.381831864466054"
        iyz="-5.12287437923494E-05"
        izz="0.379772548456655" />
    </inertial>
    <visual>
      <origin
        xyz="0 0 0"
        rpy="0 0 0" />
      <geometry>
        <mesh
          filename="package://hsr_description/meshes/br606/link2.STL" />
      </geometry>
      <material
        name="">
        <color
          rgba="0.250980392156863 0.250980392156863 0.250980392156863 1" />
      </material>
    </visual>
    <collision>
      <origin
        xyz="0 0 0"
        rpy="0 0 0" />
      <geometry>
        <mesh
          filename="package://hsr_description/meshes/br606/link2.STL" />
      </geometry>
    </collision>
  </link>
  <joint
    name="joint_2"
    type="revolute">
    <origin
      xyz="0 0 -0.0965"
      rpy="-2.60414512664787E-19 2.50218939158031E-21 1.57079635078175" />
    <parent
      link="link1" />
    <child
      link="link2" />
    <axis
      xyz="0 0 1" />
    <limit  lower="-3.1" upper="0" effort="28.0" velocity="3.2"/>
  <safety_controller k_position="100"
                     k_velocity="10"
                     soft_lower_limit="-3.1"
                     soft_upper_limit="0" /> 
  </joint>
  <link
    name="link3">
    <inertial>
      <origin
        xyz="0.00353725574440909 4.76623719094516E-05 0.0765648585551428"
        rpy="0 0 0" />
      <mass
        value="1.11115013215577" />
      <inertia
        ixx="0.00181207507130265"
        ixy="-8.15897686341942E-07"
        ixz="-8.10607375549069E-05"
        iyy="0.00341914497805436"
        iyz="-2.61386178037707E-08"
        izz="0.00304056546013647" />
    </inertial>
    <visual>
      <origin
        xyz="0 0 0"
        rpy="0 0 0" />
      <geometry>
        <mesh
          filename="package://hsr_description/meshes/br606/link3.STL" />
      </geometry>
      <material
        name="">
        <color
          rgba="1 1 1 1" />
      </material>
    </visual>
    <collision>
      <origin
        xyz="0 0 0"
        rpy="0 0 0" />
      <geometry>
        <mesh
          filename="package://hsr_description/meshes/br606/link3.STL" />
      </geometry>
    </collision>
  </link>
  <joint
    name="joint_3"
    type="revolute">
    <origin
      xyz="0.725999999928 0 -0.1245"
      rpy="-2.61618022719008E-33 -1.8705490199458E-25 -1.57079631299268" />
    <parent
      link="link2" />
    <child
      link="link3" />
    <axis
      xyz="0 0 1" />
    <limit  lower="-0.63" upper="3.4" effort="28.0" velocity="3.2"/>
  <safety_controller k_position="100"
                     k_velocity="10"
                     soft_lower_limit="-0.5585"
                     soft_upper_limit="3.4" /> 
  </joint>
  <link
    name="link4">
    <inertial>
      <origin
        xyz="0.00233159496554416 4.62822291380505E-07 0.30346531669814"
        rpy="0 0 0" />
      <mass
        value="3.18597657698263" />
      <inertia
        ixx="0.100556216689899"
        ixy="-8.97773998376489E-09"
        ixz="-0.00192678369752958"
        iyy="0.100584424161445"
        iyz="9.85953790614856E-07"
        izz="0.00297677714591598" />
    </inertial>
    <visual>
      <origin
        xyz="0 0 0"
        rpy="0 0 0" />
      <geometry>
        <mesh
          filename="package://hsr_description/meshes/br606/link4.STL" />
      </geometry>
      <material
        name="">
        <color
          rgba="1 0 0 1" />
      </material>
    </visual>
    <collision>
      <origin
        xyz="0 0 0"
        rpy="0 0 0" />
      <geometry>
        <mesh
          filename="package://hsr_description/meshes/br606/link4.STL" />
      </geometry>
    </collision>
  </link>
  <joint
    name="joint_4"
    type="revolute">
    <origin
      xyz="-0.630499999499992 0 0"
      rpy="0 1.5707963267949 0" />
    <parent
      link="link3" />
    <child
      link="link4" />
    <axis
      xyz="0 0 -0.999999999999999" />
    <limit  lower="-1.57" upper="1.57" effort="28.0" velocity="3.2"/>
  <safety_controller k_position="100"
                     k_velocity="10"
                     soft_lower_limit="-1.57"
                     soft_upper_limit="1.57" /> 
  </joint>
  <link
    name="link5">
    <inertial>
      <origin
        xyz="0.0464335628850828 1.34238986080337E-05 0.021533599146909"
        rpy="0 0 0" />
      <mass
        value="0.868404071249388" />
      <inertia
        ixx="0.00215689936272495"
        ixy="-1.57018649810158E-08"
        ixz="-1.86461968066964E-05"
        iyy="0.00196991648067436"
        iyz="-6.38364126417243E-07"
        izz="0.000809062204349609" />
    </inertial>
    <visual>
      <origin
        xyz="0 0 0"
        rpy="0 0 0" />
      <geometry>
        <mesh
          filename="package://hsr_description/meshes/br606/link5.STL" />
      </geometry>
      <material
        name="">
        <color
          rgba="1 0 0 1" />
      </material>
    </visual>
    <collision>
      <origin
        xyz="0 0 0"
        rpy="0 0 0" />
      <geometry>
        <mesh
          filename="package://hsr_description/meshes/br606/link5.STL" />
      </geometry>
    </collision>
  </link>
  <joint
    name="joint_5"
    type="revolute">
    <origin
      xyz="0.091 0 0"
      rpy="0 1.5708 0" />
    <parent
      link="link4" />
    <child
      link="link5" />
    <axis
      xyz="0 0 -1" />
    <limit  lower="-1.68" upper="1.68" effort="28.0" velocity="3.2"/>
  <safety_controller k_position="100"
                     k_velocity="10"
                     soft_lower_limit="-1.68"
                     soft_upper_limit="1.68" /> 
  </joint>
  <link
    name="link6">
    <inertial>
      <origin
        xyz="-8.65882064007284E-05 8.6588206473559E-05 -0.0107649485573491"
        rpy="0 0 0" />
      <mass
        value="0.0270769176823693" />
      <inertia
        ixx="5.43734063572495E-06"
        ixy="-1.00108295474267E-07"
        ixz="4.39894702392336E-09"
        iyy="5.43734063575559E-06"
        iyz="-4.39894701843006E-09"
        izz="1.01791524144431E-05" />
    </inertial>
    <visual>
      <origin
        xyz="0 0 0"
        rpy="0 0 0" />
      <geometry>
        <mesh
          filename="package://hsr_description/meshes/br606/link6.STL" />
      </geometry>
      <material
        name="">
        <color
          rgba="0.61569 0.64314 0.67451 1" />
      </material>
    </visual>
    <collision>
      <origin
        xyz="0 0 0"
        rpy="0 0 0" />
      <geometry>
        <mesh
          filename="package://hsr_description/meshes/br606/link6.STL" />
      </geometry>
    </collision>
  </link>
  <joint
    name="joint_6"
    type="revolute">
    <origin
      xyz="0.122 0 0"
      rpy="1.4901E-08 1.5708 0" />
    <parent
      link="link5" />
    <child
      link="link6" />
    <axis
      xyz="0 0 1" />
    <limit  lower="-4.5" upper="4.5" effort="28.0" velocity="3.2"/>
  <safety_controller k_position="100"
                     k_velocity="10"
                     soft_lower_limit="-4.5"
                     soft_upper_limit="4.5" /> 
  </joint>


<gazebo>
    <plugin name="gazebo_ros_control" filename="libgazebo_ros_control.so">
      <robotNamespace>/</robotNamespace>
      <robotSimType>gazebo_ros_control/DefaultRobotHWSim</robotSimType>
    </plugin>
  </gazebo>

<gazebo reference="base_link">
	<material>Gazebo/FlatBlack</material>
</gazebo>
<gazebo reference="link1">
	<material>Gazebo/Red</material>
</gazebo>
<gazebo reference="link2">
	<material>Gazebo/Grey</material>
</gazebo>
<gazebo reference="link3">
	<material>Gazebo/Red</material>
</gazebo>
<gazebo reference="link4">
	<material>Gazebo/Grey</material>
</gazebo>
<gazebo reference="link5">
	<material>Gazebo/Red</material>
</gazebo>
<gazebo reference="link6">
	<material>Gazebo/Black</material>
</gazebo>

  <transmission name="tran1">
    <type>transmission_interface/SimpleTransmission</type>
    <joint name="joint_1">
      <hardwareInterface>PositionJointInterface</hardwareInterface>
    </joint>
    <actuator name="motor1">
      <hardwareInterface>PositionJointInterface</hardwareInterface>
      <mechanicalReduction>1</mechanicalReduction>
    </actuator>
  </transmission>

  <transmission name="tran2">
    <type>transmission_interface/SimpleTransmission</type>
    <joint name="joint_2">
      <hardwareInterface>PositionJointInterface</hardwareInterface>
    </joint>
    <actuator name="motor2">
      <hardwareInterface>PositionJointInterface</hardwareInterface>
      <mechanicalReduction>1</mechanicalReduction>
    </actuator>
  </transmission>

  <transmission name="tran3">
    <type>transmission_interface/SimpleTransmission</type>
    <joint name="joint_3">
      <hardwareInterface>PositionJointInterface</hardwareInterface>
    </joint>
    <actuator name="motor3">
      <hardwareInterface>PositionJointInterface</hardwareInterface>
      <mechanicalReduction>1</mechanicalReduction>
    </actuator>
  </transmission>

  <transmission name="tran4">
    <type>transmission_interface/SimpleTransmission</type>
    <joint name="joint_4">
      <hardwareInterface>PositionJointInterface</hardwareInterface>
    </joint>
    <actuator name="motor4">
      <hardwareInterface>PositionJointInterface</hardwareInterface>
      <mechanicalReduction>1</mechanicalReduction>
    </actuator>
  </transmission>

  <transmission name="tran5">
    <type>transmission_interface/SimpleTransmission</type>
    <joint name="joint_5">
      <hardwareInterface>PositionJointInterface</hardwareInterface>
    </joint>
    <actuator name="motor5">
      <hardwareInterface>PositionJointInterface</hardwareInterface>
      <mechanicalReduction>1</mechanicalReduction>
    </actuator>
  </transmission>

  <transmission name="tran6">
    <type>transmission_interface/SimpleTransmission</type>
    <joint name="joint_6">
      <hardwareInterface>PositionJointInterface</hardwareInterface>
    </joint>
    <actuator name="motor6">
      <hardwareInterface>PositionJointInterface</hardwareInterface>
      <mechanicalReduction>1</mechanicalReduction>
    </actuator>
  </transmission>

</robot>
