<robot
  name="hsr_jr603">

  <link name="world"/>

  <joint name="fixed" type="fixed">
    <parent link="world"/>
    <child link="base_link"/>
	<origin
      xyz="0 0 1"
      rpy="0 0 0" />
  </joint>

  <link
    name="base_link">
    <inertial>
      <origin
        xyz="0.26352 0.011195 0.29324"
        rpy="0 0 0" />
      <mass
        value="0.00059012" />
      <inertia
        ixx="1.116E-05"
        ixy="-4.7055E-07"
        ixz="2.6217E-06"
        iyy="1.15E-05"
        iyz="1.9374E-06"
        izz="1.1293E-06" />
    </inertial>
    <visual>
      <origin
        xyz="0 0 0"
        rpy="0 0 0" />
      <geometry>
        <mesh
          filename="package://hsr_jr603/meshes/base_link.STL" />
      </geometry>
      <material
        name="">
        <color
          rgba="0 0 0 1" />
      </material>
    </visual>
    <collision>
      <origin
        xyz="0 0 0"
        rpy="0 0 0" />
      <geometry>
        <mesh
          filename="package://hsr_jr603/meshes/base_link.STL" />
      </geometry>
    </collision>
  </link>
  <link
    name="link1">
    <inertial>
      <origin
        xyz="0.26352 0.011195 0.29324"
        rpy="0 0 0" />
      <mass
        value="0.00059012" />
      <inertia
        ixx="1.116E-05"
        ixy="-4.7055E-07"
        ixz="2.6217E-06"
        iyy="1.15E-05"
        iyz="1.9374E-06"
        izz="1.1293E-06" />
    </inertial>
    <visual>
      <origin
        xyz="0 0 0"
        rpy="0 0 0" />
      <geometry>
        <mesh
          filename="package://hsr_jr603/meshes/link1.STL" />
      </geometry>
      <material
        name="">
        <color
          rgba="0.6 0.19 0.0588 1" />
      </material>
    </visual>
    <collision>
      <origin
        xyz="0 0 0"
        rpy="0 0 0" />
      <geometry>
        <mesh
          filename="package://hsr_jr603/meshes/link1.STL" />
      </geometry>
    </collision>
  </link>
  <joint
    name="joint_1"
    type="continuous">
    <origin
      xyz="0 0 0"
      rpy="-1.0992E-17 -1.7466E-16 -5.4991E-16" />
    <parent
      link="base_link" />
    <child
      link="link1" />
    <axis
      xyz="0 0 -1" />
    <limit
      lower="-3.412119"
      upper="3.412119"
      effort="0"
      velocity="0" />
  </joint>
  <link
    name="link2">
    <inertial>
      <origin
        xyz="0.33475 1.3218E-05 0.056499"
        rpy="0 0 0" />
      <mass
        value="0.00010323" />
      <inertia
        ixx="0"
        ixy="0"
        ixz="0"
        iyy="0"
        iyz="0"
        izz="0" />
    </inertial>
    <visual>
      <origin
        xyz="0 0 0"
        rpy="0 0 0" />
      <geometry>
        <mesh
          filename="package://hsr_jr603/meshes/link2.STL" />
      </geometry>
      <material
        name="">
        <color
          rgba="0.6 0.19 0.0588 1" />
      </material>
    </visual>
    <collision>
      <origin
        xyz="0 0 0"
        rpy="0 0 0" />
      <geometry>
        <mesh
          filename="package://hsr_jr603/meshes/link2.STL" />
      </geometry>
    </collision>
  </link>
  <joint
    name="joint_2"
    type="continuous">
    <origin
      xyz="0 0.0075 0"
      rpy="-1.5708 6.364E-17 -8.6055E-19" />
    <parent
      link="link1" />
    <child
      link="link2" />
    <axis
      xyz="0 0 1" />
    <limit
      lower="-3.132866"
      upper="0"
      effort="0"
      velocity="0" />
  </joint>
  <link
    name="link3">
    <inertial>
      <origin
        xyz="-0.020477 -0.29324 0.011195"
        rpy="0 0 0" />
      <mass
        value="0.00059012" />
      <inertia
        ixx="1.116E-05"
        ixy="-2.6217E-06"
        ixz="-4.7055E-07"
        iyy="1.1293E-06"
        iyz="-1.9374E-06"
        izz="1.15E-05" />
    </inertial>
    <visual>
      <origin
        xyz="0 0 0"
        rpy="0 0 0" />
      <geometry>
        <mesh
          filename="package://hsr_jr603/meshes/link3.STL" />
      </geometry>
      <material
        name="">
        <color
          rgba="0.6 0.19 0.0588 1" />
      </material>
    </visual>
    <collision>
      <origin
        xyz="0 0 0"
        rpy="0 0 0" />
      <geometry>
        <mesh
          filename="package://hsr_jr603/meshes/link3.STL" />
      </geometry>
    </collision>
  </link>
  <joint
    name="joint_3"
    type="continuous">
    <origin
      xyz="0.284 0 -0.0075"
      rpy="-1.2235E-19 -6.2402E-19 2.3592E-16" />
    <parent
      link="link2" />
    <child
      link="link3" />
    <axis
      xyz="0 0 1" />
    <limit
      lower="-0.340339"
      upper="4.180064"
      effort="0"
      velocity="0" />
  </joint>
  <link
    name="link4">
    <inertial>
      <origin
        xyz="0.0095235 0.011195 0.29324"
        rpy="0 0 0" />
      <mass
        value="0.00059012" />
      <inertia
        ixx="1.116E-05"
        ixy="-4.7055E-07"
        ixz="2.6217E-06"
        iyy="1.15E-05"
        iyz="1.9374E-06"
        izz="1.1293E-06" />
    </inertial>
    <visual>
      <origin
        xyz="0 0 0"
        rpy="0 0 0" />
      <geometry>
        <mesh
          filename="package://hsr_jr603/meshes/link4.STL" />
      </geometry>
      <material
        name="">
        <color
          rgba="0.6 0.19 0.0588 1" />
      </material>
    </visual>
    <collision>
      <origin
        xyz="0 0 0"
        rpy="0 0 0" />
      <geometry>
        <mesh
          filename="package://hsr_jr603/meshes/link4.STL" />
      </geometry>
    </collision>
  </link>
  <joint
    name="joint_4"
    type="continuous">
    <origin
      xyz="-0.03 0 0"
      rpy="1.5708 2.8877E-16 7.8886E-31" />
    <parent
      link="link3" />
    <child
      link="link4" />
    <axis
      xyz="0 0 1" />
    <limit
      lower="-3.132866"
      upper="3.132866"
      effort="0"
      velocity="0" />
  </joint>
  <link
    name="link5">
    <inertial>
      <origin
        xyz="-5.5511E-17 -0.0681 9.4258E-17"
        rpy="0 0 0" />
      <mass
        value="0.00038537" />
      <inertia
        ixx="4.1921E-08"
        ixy="-1.31E-22"
        ixz="3.1733E-22"
        iyy="8.3841E-08"
        iyz="1.9667E-23"
        izz="4.1921E-08" />
    </inertial>
    <visual>
      <origin
        xyz="0 0 0"
        rpy="0 0 0" />
      <geometry>
        <mesh
          filename="package://hsr_jr603/meshes/link5.STL" />
      </geometry>
      <material
        name="">
        <color
          rgba="0.6 0.19 0.0588 1" />
      </material>
    </visual>
    <collision>
      <origin
        xyz="0 0 0"
        rpy="0 0 0" />
      <geometry>
        <mesh
          filename="package://hsr_jr603/meshes/link5.STL" />
      </geometry>
    </collision>
  </link>
  <joint
    name="joint_5"
    type="continuous">
    <origin
      xyz="0 0 0.2865"
      rpy="-1.5708 1.1096E-16 2.8115E-16" />
    <parent
      link="link4" />
    <child
      link="link5" />
    <axis
      xyz="0 0 1" />
    <limit
      lower="-1.998402"
      upper="1.998402"
      effort="0"
      velocity="0" />
  </joint>
  <link
    name="link6">
    <inertial>
      <origin
        xyz="-8.912E-16 -0.026745 -0.0094771"
        rpy="0 0 0" />
      <mass
        value="0.00010153" />
      <inertia
        ixx="0"
        ixy="0"
        ixz="0"
        iyy="0"
        iyz="0"
        izz="0" />
    </inertial>
    <visual>
      <origin
        xyz="0 0 0"
        rpy="0 0 0" />
      <geometry>
        <mesh
          filename="package://hsr_jr603/meshes/link6.STL" />
      </geometry>
      <material
        name="">
        <color
          rgba="0 0 0 1" />
      </material>
    </visual>
    <collision>
      <origin
        xyz="0 0 0"
        rpy="0 0 0" />
      <geometry>
        <mesh
          filename="package://hsr_jr603/meshes/link6.STL" />
      </geometry>
    </collision>
  </link>
  <joint
    name="joint_6"
    type="continuous">
    <origin
      xyz="0 -0.0815 0"
      rpy="-1.3342 1.5708 -2.905" />
    <parent
      link="link5" />
    <child
      link="link6" />
    <axis
      xyz="0 0 1" />
    <limit
      lower="-6.274459"
      upper="6.274459"
      effort="0"
      velocity="0" />
  </joint>

<gazebo>
    <plugin name="gazebo_ros_control" filename="libgazebo_ros_control.so">
      <robotNamespace>/</robotNamespace>
      <robotSimType>gazebo_ros_control/DefaultRobotHWSim</robotSimType>
    </plugin>
  </gazebo>

<gazebo reference="base_link">
	<material>Gazebo/FlatBlack</material>
</gazebo>
<gazebo reference="link1">
	<material>Gazebo/Red</material>
</gazebo>
<gazebo reference="link2">
	<material>Gazebo/Grey</material>
</gazebo>
<gazebo reference="link3">
	<material>Gazebo/Red</material>
</gazebo>
<gazebo reference="link4">
	<material>Gazebo/Grey</material>
</gazebo>
<gazebo reference="link5">
	<material>Gazebo/Red</material>
</gazebo>
<gazebo reference="link6">
	<material>Gazebo/Black</material>
</gazebo>

  <transmission name="tran1">
    <type>transmission_interface/SimpleTransmission</type>
    <joint name="joint_1">
      <hardwareInterface>PositionJointInterface</hardwareInterface>
    </joint>
    <actuator name="motor1">
      <hardwareInterface>PositionJointInterface</hardwareInterface>
      <mechanicalReduction>1</mechanicalReduction>
    </actuator>
  </transmission>

  <transmission name="tran2">
    <type>transmission_interface/SimpleTransmission</type>
    <joint name="joint_2">
      <hardwareInterface>PositionJointInterface</hardwareInterface>
    </joint>
    <actuator name="motor2">
      <hardwareInterface>PositionJointInterface</hardwareInterface>
      <mechanicalReduction>1</mechanicalReduction>
    </actuator>
  </transmission>

  <transmission name="tran3">
    <type>transmission_interface/SimpleTransmission</type>
    <joint name="joint_3">
      <hardwareInterface>PositionJointInterface</hardwareInterface>
    </joint>
    <actuator name="motor3">
      <hardwareInterface>PositionJointInterface</hardwareInterface>
      <mechanicalReduction>1</mechanicalReduction>
    </actuator>
  </transmission>

  <transmission name="tran4">
    <type>transmission_interface/SimpleTransmission</type>
    <joint name="joint_4">
      <hardwareInterface>PositionJointInterface</hardwareInterface>
    </joint>
    <actuator name="motor4">
      <hardwareInterface>PositionJointInterface</hardwareInterface>
      <mechanicalReduction>1</mechanicalReduction>
    </actuator>
  </transmission>

  <transmission name="tran5">
    <type>transmission_interface/SimpleTransmission</type>
    <joint name="joint_5">
      <hardwareInterface>PositionJointInterface</hardwareInterface>
    </joint>
    <actuator name="motor5">
      <hardwareInterface>PositionJointInterface</hardwareInterface>
      <mechanicalReduction>1</mechanicalReduction>
    </actuator>
  </transmission>

  <transmission name="tran6">
    <type>transmission_interface/SimpleTransmission</type>
    <joint name="joint_6">
      <hardwareInterface>PositionJointInterface</hardwareInterface>
    </joint>
    <actuator name="motor6">
      <hardwareInterface>PositionJointInterface</hardwareInterface>
      <mechanicalReduction>1</mechanicalReduction>
    </actuator>
  </transmission>


</robot>
