<robot
  name="hsr_jr605">
  <link
    name="base_link">
    <inertial>
      <origin
        xyz="-0.042985 3.4724E-08 0.11956"
        rpy="0 0 0" />
      <mass
        value="9.9325" />
      <inertia
        ixx="0.00017367"
        ixy="-2.9156E-10"
        ixz="-0.00022956"
        iyy="0.0013028"
        iyz="-5.523E-11"
        izz="0.0013433" />
    </inertial>
    <visual>
      <origin
        xyz="0 0 0"
        rpy="0 0 0" />
      <geometry>
        <mesh
          filename="package://hsr_description/meshes/jr605/base_link.STL" />
      </geometry>
      <material
        name="">
        <color
          rgba="0.25098 0.25098 0.25098 1" />
      </material>
    </visual>
    <collision>
      <origin
        xyz="0 0 0"
        rpy="0 0 0" />
      <geometry>
        <mesh
          filename="package://hsr_description/meshes/jr605/base_link.STL" />
      </geometry>
    </collision>
  </link>
  <link
    name="link1">
    <inertial>
      <origin
        xyz="2.2702E-05 0.00096249 -0.021354"
        rpy="0 0 0" />
      <mass
        value="3.7652" />
      <inertia
        ixx="6.6911E-06"
        ixy="-5.1617E-08"
        ixz="-3.4495E-06"
        iyy="1.904E-05"
        iyz="1.5461E-07"
        izz="1.5184E-05" />
    </inertial>
    <visual>
      <origin
        xyz="0 0 0"
        rpy="0 0 0" />
      <geometry>
        <mesh
          filename="package://hsr_description/meshes/jr605/link1.STL" />
      </geometry>
      <material
        name="">
        <color
          rgba="1 0 0 1" />
      </material>
    </visual>
    <collision>
      <origin
        xyz="0 0 0"
        rpy="0 0 0" />
      <geometry>
        <mesh
          filename="package://hsr_description/meshes/jr605/link1.STL" />
      </geometry>
    </collision>
  </link>
  <joint
    name="joint_1"
    type="revolute">
    <origin
      xyz="0 0 0.3535"
      rpy="0 0 0" />
    <parent
      link="base_link" />
    <child
      link="link1" />
    <axis
      xyz="0 0 1" />
    <limit
      lower="-3.4907"
      upper="3.4907"
      effort="0"
      velocity="0" />
  </joint>
  <link
    name="link2">
    <inertial>
      <origin
        xyz="0.16918 4.7044E-05 -0.00057704"
        rpy="0 0 0" />
      <mass
        value="8.1648" />
      <inertia
        ixx="6.0909E-06"
        ixy="6.8786E-10"
        ixz="-5.6336E-07"
        iyy="1.2447E-05"
        iyz="9.3589E-10"
        izz="9.9674E-06" />
    </inertial>
    <visual>
      <origin
        xyz="0 0 0"
        rpy="0 0 0" />
      <geometry>
        <mesh
          filename="package://hsr_description/meshes/jr605/link2.STL" />
      </geometry>
      <material
        name="">
        <color
          rgba="1 0 0 1" />
      </material>
    </visual>
    <collision>
      <origin
        xyz="0 0 0"
        rpy="0 0 0" />
      <geometry>
        <mesh
          filename="package://hsr_description/meshes/jr605/link2.STL" />
      </geometry>
    </collision>
  </link>
  <joint
    name="joint_2"
    type="revolute">
    <origin
      xyz="0 0 0"
      rpy="-1.5708 0 9.8233E-20" />
    <parent
      link="link1" />
    <child
      link="link2" />
    <axis
      xyz="0 0 1" />
    <limit
      lower="-3.1416"
      upper="0.0175"
      effort="0"
      velocity="0" />
  </joint>
  <link
    name="link3">
    <inertial>
      <origin
        xyz="-0.046472 -0.030742 0.00086805"
        rpy="0 0 0" />
      <mass
        value="4.2403" />
      <inertia
        ixx="3.1537E-06"
        ixy="-1.0326E-06"
        ixz="-1.7025E-08"
        iyy="4.5031E-06"
        iyz="-7.4992E-08"
        izz="4.6003E-06" />
    </inertial>
    <visual>
      <origin
        xyz="0 0 0"
        rpy="0 0 0" />
      <geometry>
        <mesh
          filename="package://hsr_description/meshes/jr605/link3.STL" />
      </geometry>
      <material
        name="">
        <color
          rgba="1 0 0 1" />
      </material>
    </visual>
    <collision>
      <origin
        xyz="0 0 0"
        rpy="0 0 0" />
      <geometry>
        <mesh
          filename="package://hsr_description/meshes/jr605/link3.STL" />
      </geometry>
    </collision>
  </link>
  <joint
    name="joint_3"
    type="revolute">
    <origin
      xyz="0.36 0 0"
      rpy="-1.2635E-17 5.072E-19 4.9915E-36" />
    <parent
      link="link2" />
    <child
      link="link3" />
    <axis
      xyz="0 0 1" />
    <limit
      lower="1.3963"
      upper="4.1888"
      effort="0"
      velocity="0" />
  </joint>
  <link
    name="link4">
    <inertial>
      <origin
        xyz="-0.00046555 7.4059E-06 0.26725"
        rpy="0 0 0" />
      <mass
        value="3.8061" />
      <inertia
        ixx="2.6826E-05"
        ixy="-1.7466E-07"
        ixz="-3.228E-06"
        iyy="2.4576E-05"
        iyz="-1.1757E-06"
        izz="1.6157E-05" />
    </inertial>
    <visual>
      <origin
        xyz="0 0 0"
        rpy="0 0 0" />
      <geometry>
        <mesh
          filename="package://hsr_description/meshes/jr605/link4.STL" />
      </geometry>
      <material
        name="">
        <color
          rgba="1 0 0 1" />
      </material>
    </visual>
    <collision>
      <origin
        xyz="0 0 0"
        rpy="0 0 0" />
      <geometry>
        <mesh
          filename="package://hsr_description/meshes/jr605/link4.STL" />
      </geometry>
    </collision>
  </link>
  <joint
    name="joint_4"
    type="revolute">
    <origin
      xyz="-0.09 0 0"
      rpy="1.5708 0 0" />
    <parent
      link="link3" />
    <child
      link="link4" />
    <axis
      xyz="0 0 -1" />
    <limit
      lower="-3.1416"
      upper="3.1416"
      effort="0"
      velocity="0" />
  </joint>
  <link
    name="link5">
    <inertial>
      <origin
        xyz="1.2455E-05 -0.014809 -0.00026987"
        rpy="0 0 0" />
      <mass
        value="1.0252" />
      <inertia
        ixx="0"
        ixy="0"
        ixz="0"
        iyy="0"
        iyz="0"
        izz="0" />
    </inertial>
    <visual>
      <origin
        xyz="0 0 0"
        rpy="0 0 0" />
      <geometry>
        <mesh
          filename="package://hsr_description/meshes/jr605/link5.STL" />
      </geometry>
      <material
        name="">
        <color
          rgba="1 0 0 1" />
      </material>
    </visual>
    <collision>
      <origin
        xyz="0 0 0"
        rpy="0 0 0" />
      <geometry>
        <mesh
          filename="package://hsr_description/meshes/jr605/link5.STL" />
      </geometry>
    </collision>
  </link>
  <joint
    name="joint_5"
    type="revolute">
    <origin
      xyz="0 0 0.3765"
      rpy="-1.5708 -1.3878E-17 -4.4702E-16" />
    <parent
      link="link4" />
    <child
      link="link5" />
    <axis
      xyz="0 0 1" />
    <limit
      lower="-2.0071"
      upper="2.0071"
      effort="0"
      velocity="0" />
  </joint>
  <link
    name="link6">
    <inertial>
      <origin
        xyz="2.9332E-05 0.00012753 -0.0062778"
        rpy="0 0 0" />
      <mass
        value="0.025338" />
      <inertia
        ixx="0"
        ixy="0"
        ixz="0"
        iyy="0"
        iyz="0"
        izz="0" />
    </inertial>
    <visual>
      <origin
        xyz="0 0 0"
        rpy="0 0 0" />
      <geometry>
        <mesh
          filename="package://hsr_description/meshes/jr605/link6.STL" />
      </geometry>
      <material
        name="">
        <color
          rgba="1 0 0 1" />
      </material>
    </visual>
    <collision>
      <origin
        xyz="0 0 0"
        rpy="0 0 0" />
      <geometry>
        <mesh
          filename="package://hsr_description/meshes/jr605/link6.STL" />
      </geometry>
    </collision>
  </link>
  <joint
    name="joint_6"
    type="revolute">
    <origin
      xyz="0 -0.119 0"
      rpy="1.5708 0.042291 1.1639E-17" />
    <parent
      link="link5" />
    <child
      link="link6" />
    <axis
      xyz="0 0 -1" />
    <limit
      lower="-6.2832"
      upper="6.2832"
      effort="0"
      velocity="0" />
  </joint>
</robot>
