<?xml version="1.0"?>

<robot
  name="hsr_newtran_gripper">

  <link
    name="gripper_base_link">
    <inertial>
      <origin
        xyz="0.0018672 -1.7347E-17 0.049664"
        rpy="0 0 0" />
      <mass
        value="0.042402" />
      <inertia
        ixx="1.6367E-05"
        ixy="1.7054E-20"
        ixz="-4.4871E-07"
        iyy="2.8869E-05"
        iyz="3.6507E-21"
        izz="1.2501E-05" />
    </inertial>
    <visual>
      <origin
        xyz="0 0 0"
        rpy="0 0 0" />
      <geometry>
        <mesh
          filename="package://hsr_description/meshes/new_tran_gripper/base_link.STL" />
      </geometry>
      <material
        name="">
        <color
          rgba="0.8 0.8 0.5 1" />
      </material>
    </visual>
    <collision>
      <origin
        xyz="0 0 0"
        rpy="0 0 0" />
      <geometry>
        <mesh
          filename="package://hsr_description/meshes/new_tran_gripper/base_link.STL" />
      </geometry>
    </collision>
  </link>
  <link
    name="grisper_body_link">
    <inertial>
      <origin
        xyz="2.8423E-05 -0.00087553 -0.009974"
        rpy="0 0 0" />
      <mass
        value="0.038796" />
      <inertia
        ixx="0"
        ixy="0"
        ixz="0"
        iyy="0"
        iyz="0"
        izz="0" />
    </inertial>
    <visual>
      <origin
        xyz="0 0 0"
        rpy="0 0 0" />
      <geometry>
        <mesh
          filename="package://hsr_description/meshes/new_tran_gripper/grisper_body_link.STL" />
      </geometry>
      <material
        name="">
        <color
          rgba="0.8 0.8 0.5 1" />
      </material>
    </visual>
    <collision>
      <origin
        xyz="0 0 0"
        rpy="0 0 0" />
      <geometry>
        <mesh
          filename="package://hsr_description/meshes/new_tran_gripper/grisper_body_link.STL" />
      </geometry>
    </collision>
  </link>
  <joint
    name="grisper_body_joint"
    type="fixed">
    <origin
      xyz="0 -0.01 0.0935"
      rpy="1.5708 -9.5708E-17 2.4114E-16" />
    <parent
      link="gripper_base_link" />
    <child
      link="grisper_body_link" />
    <axis
      xyz="0 0 0" />
  </joint>
  <link
    name="right_finger_1_link">
    <inertial>
      <origin
        xyz="-2.9239E-06 0.016823 0.008979"
        rpy="0 0 0" />
      <mass
        value="0.0023503" />
      <inertia
        ixx="0"
        ixy="0"
        ixz="0"
        iyy="0"
        iyz="0"
        izz="0" />
    </inertial>
    <visual>
      <origin
        xyz="0 0 0"
        rpy="0 0 0" />
      <geometry>
        <mesh
          filename="package://hsr_description/meshes/new_tran_gripper/right_finger_1_link.STL" />
      </geometry>
      <material
        name="">
        <color
          rgba="0.8 0.8 0.5 1" />
      </material>
    </visual>
    <collision>
      <origin
        xyz="0 0 0"
        rpy="0 0 0" />
      <geometry>
        <mesh
          filename="package://hsr_description/meshes/new_tran_gripper/right_finger_1_link.STL" />
      </geometry>
    </collision>
  </link>
  <joint
    name="right_finger_1_joint"
    type="continuous">
    <origin
      xyz="0.04 0.036 -0.019"
      rpy="8.6736E-17 5.5467E-32 -0.33984" />
    <parent
      link="grisper_body_link" />
    <child
      link="right_finger_1_link" />
    <axis
      xyz="0 0 1" />
  </joint>
  <link
    name="right_finger_2_link">
    <inertial>
      <origin
        xyz="-0.0085798 0.0066139 0.006"
        rpy="0 0 0" />
      <mass
        value="0.0020017" />
      <inertia
        ixx="0"
        ixy="0"
        ixz="0"
        iyy="0"
        iyz="0"
        izz="0" />
    </inertial>
    <visual>
      <origin
        xyz="0 0 0"
        rpy="0 0 0" />
      <geometry>
        <mesh
          filename="package://hsr_description/meshes/new_tran_gripper/right_finger_2_link.STL" />
      </geometry>
      <material
        name="">
        <color
          rgba="0.8 0.8 0.5 1" />
      </material>
    </visual>
    <collision>
      <origin
        xyz="0 0 0"
        rpy="0 0 0" />
      <geometry>
        <mesh
          filename="package://hsr_description/meshes/new_tran_gripper/right_finger_2_link.STL" />
      </geometry>
    </collision>
  </link>
  <joint
    name="right_finger_2_joint"
    type="continuous">
    <origin
      xyz="0 0.042 0.003"
      rpy="-8.1776E-17 2.8912E-17 0.33984" />
    <parent
      link="right_finger_1_link" />
    <child
      link="right_finger_2_link" />
    <axis
      xyz="0 0 1" />
  </joint>
  <link
    name="right_finger_end_link">
    <inertial>
      <origin
        xyz="-0.01811 -0.009 -0.00041937"
        rpy="0 0 0" />
      <mass
        value="0.0016908" />
      <inertia
        ixx="0"
        ixy="0"
        ixz="0"
        iyy="0"
        iyz="0"
        izz="0" />
    </inertial>
    <visual>
      <origin
        xyz="0 0 0"
        rpy="0 0 0" />
      <geometry>
        <mesh
          filename="package://hsr_description/meshes/new_tran_gripper/right_finger_end_link.STL" />
      </geometry>
      <material
        name="">
        <color
          rgba="0.8 0.8 0.5 1" />
      </material>
    </visual>
    <collision>
      <origin
        xyz="0 0 0"
        rpy="0 0 0" />
      <geometry>
        <mesh
          filename="package://hsr_description/meshes/new_tran_gripper/right_finger_end_link.STL" />
      </geometry>
    </collision>
  </link>
  <joint
    name="right_finger_end_joint"
    type="fixed">
    <origin
      xyz="-0.0145 -0.0035 -0.003"
      rpy="-1.5708 0 -1.5708" />
    <parent
      link="right_finger_2_link" />
    <child
      link="right_finger_end_link" />
    <axis
      xyz="0 0 0" />
  </joint>
  <link
    name="left_finger_1_link">
    <inertial>
      <origin
        xyz="-2.924E-06 0.016823 0.008979"
        rpy="0 0 0" />
      <mass
        value="0.0023503" />
      <inertia
        ixx="0"
        ixy="0"
        ixz="0"
        iyy="0"
        iyz="0"
        izz="0" />
    </inertial>
    <visual>
      <origin
        xyz="0 0 0"
        rpy="0 0 0" />
      <geometry>
        <mesh
          filename="package://hsr_description/meshes/new_tran_gripper/left_finger_1_link.STL" />
      </geometry>
      <material
        name="">
        <color
          rgba="0.8 0.8 0.5 1" />
      </material>
    </visual>
    <collision>
      <origin
        xyz="0 0 0"
        rpy="0 0 0" />
      <geometry>
        <mesh
          filename="package://hsr_description/meshes/new_tran_gripper/left_finger_1_link.STL" />
      </geometry>
    </collision>
  </link>
  <joint
    name="left_finger_1_joint"
    type="continuous">
    <origin
      xyz="-0.04 0.036 -0.019"
      rpy="8.6736E-17 0 0.33984" />
    <parent
      link="grisper_body_link" />
    <child
      link="left_finger_1_link" />
    <axis
      xyz="0 0 1" />
  </joint>
  <link
    name="left_finger_2_link">
    <inertial>
      <origin
        xyz="-0.0085798 0.0066139 0.006"
        rpy="0 0 0" />
      <mass
        value="0.0020017" />
      <inertia
        ixx="0"
        ixy="0"
        ixz="0"
        iyy="0"
        iyz="0"
        izz="0" />
    </inertial>
    <visual>
      <origin
        xyz="0 0 0"
        rpy="0 0 0" />
      <geometry>
        <mesh
          filename="package://hsr_description/meshes/new_tran_gripper/left_finger_2_link.STL" />
      </geometry>
      <material
        name="">
        <color
          rgba="0.8 0.8 0.5 1" />
      </material>
    </visual>
    <collision>
      <origin
        xyz="0 0 0"
        rpy="0 0 0" />
      <geometry>
        <mesh
          filename="package://hsr_description/meshes/new_tran_gripper/left_finger_2_link.STL" />
      </geometry>
    </collision>
  </link>
  <joint
    name="left_finger_2_joint"
    type="continuous">
    <origin
      xyz="0 0.042 0.015"
      rpy="-3.1416 2.8912E-17 2.8018" />
    <parent
      link="left_finger_1_link" />
    <child
      link="left_finger_2_link" />
    <axis
      xyz="0 0 1" />
  </joint>
  <link
    name="left_finger_end_link">
    <inertial>
      <origin
        xyz="-0.01811 -0.009 -0.00041937"
        rpy="0 0 0" />
      <mass
        value="0.0016908" />
      <inertia
        ixx="0"
        ixy="0"
        ixz="0"
        iyy="0"
        iyz="0"
        izz="0" />
    </inertial>
    <visual>
      <origin
        xyz="0 0 0"
        rpy="0 0 0" />
      <geometry>
        <mesh
          filename="package://hsr_description/meshes/new_tran_gripper/left_finger_end_link.STL" />
      </geometry>
      <material
        name="">
        <color
          rgba="0.8 0.8 0.5 1" />
      </material>
    </visual>
    <collision>
      <origin
        xyz="0 0 0"
        rpy="0 0 0" />
      <geometry>
        <mesh
          filename="package://hsr_description/meshes/new_tran_gripper/left_finger_end_link.STL" />
      </geometry>
    </collision>
  </link>
  <joint
    name="left_finger_end_joint"
    type="fixed">
    <origin
      xyz="-0.0145 -0.0035 -0.003"
      rpy="-1.5708 0 -1.5708" />
    <parent
      link="left_finger_2_link" />
    <child
      link="left_finger_end_link" />
    <axis
      xyz="0 0 0" />
  </joint>

  <link name="pick_gripper_link">
     <visual>
       <origin xyz="0 0 0" rpy="0 0 0" />
       <geometry>
          <box size="0.001 0.0005 0.0005"/>
       </geometry>
     </visual>
  </link>

  <transmission name="tran1">
    <type>transmission_interface/SimpleTransmission</type>
    <joint name="right_finger_1_joint">
      <hardwareInterface>PositionJointInterface</hardwareInterface>
    </joint>
    <actuator name="right_finger_1_motor">
      <hardwareInterface>PositionJointInterface</hardwareInterface>
      <mechanicalReduction>1</mechanicalReduction>
    </actuator>
  </transmission>

  <transmission name="tran2">
    <type>transmission_interface/SimpleTransmission</type>
    <joint name="right_finger_2_joint">
      <hardwareInterface>PositionJointInterface</hardwareInterface>
    </joint>
    <actuator name="right_finger_2_motor">
      <hardwareInterface>PositionJointInterface</hardwareInterface>
      <mechanicalReduction>1</mechanicalReduction>
    </actuator>
  </transmission>

  <transmission name="tran3">
    <type>transmission_interface/SimpleTransmission</type>
    <joint name="left_finger_1_joint">
      <hardwareInterface>PositionJointInterface</hardwareInterface>
    </joint>
    <actuator name="left_finger_1_motor">
      <hardwareInterface>PositionJointInterface</hardwareInterface>
      <mechanicalReduction>1</mechanicalReduction>
    </actuator>
  </transmission>

  <transmission name="tran4">
    <type>transmission_interface/SimpleTransmission</type>
    <joint name="left_finger_2_joint">
      <hardwareInterface>PositionJointInterface</hardwareInterface>
    </joint>
    <actuator name="left_finger_2_motor">
      <hardwareInterface>PositionJointInterface</hardwareInterface>
      <mechanicalReduction>1</mechanicalReduction>
    </actuator>
  </transmission>  

</robot>
