<robot
  name="hsr_br606">

  <link name="world"/>

  <joint name="fixed" type="fixed">
    <parent link="world"/>
    <child link="base_link"/>
  </joint>

  <link
    name="base_link">
    <inertial>
      <origin
        xyz="-0.0404819769275653 1.05073553191559E-08 -0.284689129421307"
        rpy="0 0 0" />
      <mass
        value="10.9537086254326" />
      <inertia
        ixx="3.56348268655843E-06"
        ixy="-1.21486179086503E-13"
        ixz="-1.38643083426369E-06"
        iyy="3.54846152801012E-06"
        iyz="-2.25230421729927E-13"
        izz="1.97156369598741E-06" />
    </inertial>
    <visual>
      <origin
        xyz="0 0 0"
        rpy="0 0 0" />
      <geometry>
        <mesh
          filename="package://hsr_description/meshes/br606/base_link.STL" />
      </geometry>
      <material
        name="">
        <color
          rgba="0.752941176470588 0.752941176470588 0.752941176470588 1" />
      </material>
    </visual>
    <collision>
      <origin
        xyz="0 0 0"
        rpy="0 0 0" />
      <geometry>
        <mesh
          filename="package://hsr_description/meshes/br606/base_link.STL" />
      </geometry>
    </collision>
  </link>
  <link
    name="link1">
    <inertial>
      <origin
        xyz="-0.0429700166186563 0.000232424976987443 0.0163307442364727"
        rpy="0 0 0" />
      <mass
        value="4.59272942117021" />
      <inertia
        ixx="0"
        ixy="0"
        ixz="0"
        iyy="0"
        iyz="0"
        izz="0" />
    </inertial>
    <visual>
      <origin
        xyz="0 0 0"
        rpy="0 0 0" />
      <geometry>
        <mesh
          filename="package://hsr_description/meshes/br606/link1.STL" />
      </geometry>
      <material
        name="">
        <color
          rgba="1 0 0 1" />
      </material>
    </visual>
    <collision>
      <origin
        xyz="0 0 0"
        rpy="0 0 0" />
      <geometry>
        <mesh
          filename="package://hsr_description/meshes/br606/link1.STL" />
      </geometry>
    </collision>
  </link>
  <joint
    name="joint1"
    type="revolute">
    <origin
      xyz="0 0 0"
      rpy="-1.5707963267949 -1.5707963267949 0" />
    <parent
      link="base_link" />
    <child
      link="link1" />
    <axis
      xyz="1 0 0" />
    <limit  lower="-2.71415" upper="2.71415" effort="28.0" velocity="3.2"/>
  <safety_controller k_position="100"
                     k_velocity="10"
                     soft_lower_limit="-2.6179"
                     soft_upper_limit="2.6179" /> 
  </joint>
  <link
    name="link2">
    <inertial>
      <origin
        xyz="0.394646808040514 -0.000110226409981429 0.005513805370364"
        rpy="0 0 0" />
      <mass
        value="6.56007074220098" />
      <inertia
        ixx="0"
        ixy="0"
        ixz="0"
        iyy="0"
        iyz="0"
        izz="0" />
    </inertial>
    <visual>
      <origin
        xyz="0 0 0"
        rpy="0 0 0" />
      <geometry>
        <mesh
          filename="package://hsr_description/meshes/br606/link2.STL" />
      </geometry>
      <material
        name="">
        <color
          rgba="0.250980392156863 0.250980392156863 0.250980392156863 1" />
      </material>
    </visual>
    <collision>
      <origin
        xyz="0 0 0"
        rpy="0 0 0" />
      <geometry>
        <mesh
          filename="package://hsr_description/meshes/br606/link2.STL" />
      </geometry>
    </collision>
  </link>
  <joint
    name="joint2"
    type="revolute">
    <origin
      xyz="0 0 -0.0965"
      rpy="-2.60414512664787E-19 2.50218939158031E-21 1.57079635078175" />
    <parent
      link="link1" />
    <child
      link="link2" />
    <axis
      xyz="0 0 1" />
    <limit  lower="-3.1" upper="0" effort="28.0" velocity="3.2"/>
  <safety_controller k_position="100"
                     k_velocity="10"
                     soft_lower_limit="-3.1"
                     soft_upper_limit="0" /> 
  </joint>
  <link
    name="link3">
    <inertial>
      <origin
        xyz="-0.00353730365776206 4.7138384283385E-05 0.00943526728921718"
        rpy="0 0 0" />
      <mass
        value="1.11116815174246" />
      <inertia
        ixx="0"
        ixy="0"
        ixz="0"
        iyy="0"
        iyz="0"
        izz="0" />
    </inertial>
    <visual>
      <origin
        xyz="0 0 0"
        rpy="0 0 0" />
      <geometry>
        <mesh
          filename="package://hsr_description/meshes/br606/link3.STL" />
      </geometry>
      <material
        name="">
        <color
          rgba="1 1 1 1" />
      </material>
    </visual>
    <collision>
      <origin
        xyz="0 0 0"
        rpy="0 0 0" />
      <geometry>
        <mesh
          filename="package://hsr_description/meshes/br606/link3.STL" />
      </geometry>
    </collision>
  </link>
  <joint
    name="joint3"
    type="revolute">
    <origin
      xyz="0.725999999928 0 -0.1245"
      rpy="-2.61618022719008E-33 -1.8705490199458E-25 -1.57079631299268" />
    <parent
      link="link2" />
    <child
      link="link3" />
    <axis
      xyz="0 0 1" />
    <limit  lower="-0.63" upper="3.4" effort="28.0" velocity="3.2"/>
  <safety_controller k_position="100"
                     k_velocity="10"
                     soft_lower_limit="-0.5585"
                     soft_upper_limit="3.4" /> 
  </joint>
  <link
    name="link4">
    <inertial>
      <origin
        xyz="0.0023315887798423 -4.73547398738283E-07 0.255534722375136"
        rpy="0 0 0" />
      <mass
        value="3.18597528812718" />
      <inertia
        ixx="0"
        ixy="0"
        ixz="0"
        iyy="0"
        iyz="0"
        izz="0" />
    </inertial>
    <visual>
      <origin
        xyz="0 0 0"
        rpy="0 0 0" />
      <geometry>
        <mesh
          filename="package://hsr_description/meshes/br606/link4.STL" />
      </geometry>
      <material
        name="">
        <color
          rgba="1 0 0 1" />
      </material>
    </visual>
    <collision>
      <origin
        xyz="0 0 0"
        rpy="0 0 0" />
      <geometry>
        <mesh
          filename="package://hsr_description/meshes/br606/link4.STL" />
      </geometry>
    </collision>
  </link>
  <joint
    name="joint4"
    type="revolute">
    <origin
      xyz="-0.630499999499992 0 0"
      rpy="0 1.5707963267949 0" />
    <parent
      link="link3" />
    <child
      link="link4" />
    <axis
      xyz="0 0 -0.999999999999999" />
    <limit  lower="-1.57" upper="1.57" effort="28.0" velocity="3.2"/>
  <safety_controller k_position="100"
                     k_velocity="10"
                     soft_lower_limit="-1.57"
                     soft_upper_limit="1.57" /> 
  </joint>
  <link
    name="link5">
    <inertial>
      <origin
        xyz="0.021534 -1.3425E-05 -0.0010665"
        rpy="0 0 0" />
      <mass
        value="0.8684" />
      <inertia
        ixx="1.5917E-07"
        ixy="-1.8697E-10"
        ixz="-1.3172E-08"
        iyy="7.5421E-07"
        iyz="-2.3505E-12"
        izz="7.5521E-07" />
    </inertial>
    <visual>
      <origin
        xyz="0 0 0"
        rpy="0 0 0" />
      <geometry>
        <mesh
          filename="package://hsr_description/meshes/br606/link5.STL" />
      </geometry>
      <material
        name="">
        <color
          rgba="1 0 0 1" />
      </material>
    </visual>
    <collision>
      <origin
        xyz="0 0 0"
        rpy="0 0 0" />
      <geometry>
        <mesh
          filename="package://hsr_description/meshes/br606/link5.STL" />
      </geometry>
    </collision>
  </link>
  <joint
    name="joint5"
    type="revolute">
    <origin
      xyz="0.091 0 0"
      rpy="0 1.5708 0" />
    <parent
      link="link4" />
    <child
      link="link5" />
    <axis
      xyz="0 0 -1" />
    <limit  lower="-1.68" upper="1.68" effort="28.0" velocity="3.2"/>
  <safety_controller k_position="100"
                     k_velocity="10"
                     soft_lower_limit="-1.68"
                     soft_upper_limit="1.68" /> 
  </joint>
  <link
    name="link6">
    <inertial>
      <origin
        xyz="5.1514E-14 -0.00012245 -0.0062351"
        rpy="0 0 0" />
      <mass
        value="0.027077" />
      <inertia
        ixx="0"
        ixy="0"
        ixz="0"
        iyy="0"
        iyz="0"
        izz="0" />
    </inertial>
    <visual>
      <origin
        xyz="0 0 0"
        rpy="0 0 0" />
      <geometry>
        <mesh
          filename="package://hsr_description/meshes/br606/link6.STL" />
      </geometry>
      <material
        name="">
        <color
          rgba="0.61569 0.64314 0.67451 1" />
      </material>
    </visual>
    <collision>
      <origin
        xyz="0 0 0"
        rpy="0 0 0" />
      <geometry>
        <mesh
          filename="package://hsr_description/meshes/br606/link6.STL" />
      </geometry>
    </collision>
  </link>
  <joint
    name="joint6"
    type="revolute">
    <origin
      xyz="0.122 0 0"
      rpy="1.4901E-08 1.5708 0" />
    <parent
      link="link5" />
    <child
      link="link6" />
    <axis
      xyz="0 0 1" />
    <limit  lower="-4.5" upper="4.5" effort="28.0" velocity="3.2"/>
  <safety_controller k_position="100"
                     k_velocity="10"
                     soft_lower_limit="-4.5"
                     soft_upper_limit="4.5" /> 
  </joint>


<gazebo>
    <plugin name="gazebo_ros_control" filename="libgazebo_ros_control.so">
      <robotNamespace>/</robotNamespace>
      <robotSimType>gazebo_ros_control/DefaultRobotHWSim</robotSimType>
    </plugin>
  </gazebo>

  <transmission name="tran1">
    <type>transmission_interface/SimpleTransmission</type>
    <joint name="joint1">
      <hardwareInterface>PositionJointInterface</hardwareInterface>
    </joint>
    <actuator name="motor1">
      <hardwareInterface>PositionJointInterface</hardwareInterface>
      <mechanicalReduction>1</mechanicalReduction>
    </actuator>
  </transmission>

  <transmission name="tran2">
    <type>transmission_interface/SimpleTransmission</type>
    <joint name="joint2">
      <hardwareInterface>PositionJointInterface</hardwareInterface>
    </joint>
    <actuator name="motor2">
      <hardwareInterface>PositionJointInterface</hardwareInterface>
      <mechanicalReduction>1</mechanicalReduction>
    </actuator>
  </transmission>

  <transmission name="tran3">
    <type>transmission_interface/SimpleTransmission</type>
    <joint name="joint3">
      <hardwareInterface>PositionJointInterface</hardwareInterface>
    </joint>
    <actuator name="motor3">
      <hardwareInterface>PositionJointInterface</hardwareInterface>
      <mechanicalReduction>1</mechanicalReduction>
    </actuator>
  </transmission>

  <transmission name="tran4">
    <type>transmission_interface/SimpleTransmission</type>
    <joint name="joint4">
      <hardwareInterface>PositionJointInterface</hardwareInterface>
    </joint>
    <actuator name="motor4">
      <hardwareInterface>PositionJointInterface</hardwareInterface>
      <mechanicalReduction>1</mechanicalReduction>
    </actuator>
  </transmission>

  <transmission name="tran5">
    <type>transmission_interface/SimpleTransmission</type>
    <joint name="joint5">
      <hardwareInterface>PositionJointInterface</hardwareInterface>
    </joint>
    <actuator name="motor5">
      <hardwareInterface>PositionJointInterface</hardwareInterface>
      <mechanicalReduction>1</mechanicalReduction>
    </actuator>
  </transmission>

  <transmission name="tran6">
    <type>transmission_interface/SimpleTransmission</type>
    <joint name="joint6">
      <hardwareInterface>PositionJointInterface</hardwareInterface>
    </joint>
    <actuator name="motor6">
      <hardwareInterface>PositionJointInterface</hardwareInterface>
      <mechanicalReduction>1</mechanicalReduction>
    </actuator>
  </transmission>

</robot>
