<?xml version="1.0"?>
<robot name="ir100_robot" xmlns:xacro="http://ros.org/wiki/xacro">

<xacro:macro name="ir100_robot">
  <material name="OffWhite">
    <color rgba="0.8 0.8 0.8 0.9"/>
  </material>

<!--
  <link name="world"/>

  <joint name="fixed" type="fixed">
    <parent link="world"/>
    <child link="base_link"/>
	<origin
      xyz="0 0 1"
      rpy="0 0 0" />
  </joint> 
-->

  <link name="base_link" >
<!--
      <inertial>
        <mass value="0.0001" />
        <origin xyz="0 0 0" />
        <inertia ixx="0.0001" ixy="0.0" ixz="0.0"
                 iyy="0.0001" iyz="0.0"
                 izz="0.0001" />
      </inertial>
      <visual>
        <origin xyz="0 0 0" rpy="0 0 0" />
        <geometry>
          <mesh filename="package://agv_description/meshes/base_link.stl" />
        </geometry>
        <material name="OffWhite" />
      </visual>
-->
  </link>

  <link name="left_wheel_link" />
  <joint name="left_wheel_joint" type="continuous">
    <origin xyz="0 0.168 0.062" rpy="-1.5707963267949 0.343792057554545 3.14159265358979" />
    <parent link="base_link" />
    <child link="left_wheel_link" />
    <axis xyz="0 0 -1" />
  </joint>

  <link name="right_wheel_link" />
  <joint name="right_wheel_joint" type="continuous">
    <origin xyz="0 -0.168 0.062" rpy="1.5707963267949 0.343792057554545 3.14159265358979" />
    <parent link="base_link" />
    <child link="right_wheel_link" />
    <axis xyz="0 0 1" />
  </joint>

  <link name="imu_link" />
  <joint name="imu_joint" type="fixed">
    <origin xyz="-0.223 0 0.22382" rpy="0 0 0" />
    <parent link="base_link" />
    <child link="imu_link" />
  </joint>

  <link name="camera_link" />
  <joint name="camera_joint" type="fixed">
    <origin xyz="0.19717 0 0.20765" rpy="0 0.2617 0" />
    <parent link="base_link" />
    <child link="camera_link" />
  </joint>

  <link name="laser" />
  <joint name="laser_joint" type="fixed">
    <origin xyz="0.30236 0 0.287" rpy="3.141592654 0 0" />
    <parent link="base_link" />
    <child link="laser" />
  </joint>

</xacro:macro>
</robot>
