<robot
  name="hsr_co602a_gaihou">
  <link
    name="base_link2">
    <inertial>
      <origin
        xyz="-0.0024613 5.2375E-07 0.076752"
        rpy="0 0 0" />
      <mass
        value="4.8818" />
      <inertia
        ixx="0"
        ixy="0"
        ixz="0"
        iyy="0"
        iyz="0"
        izz="0" />
    </inertial>
    <visual>
      <origin
        xyz="0 0 0"
        rpy="0 0 0" />
      <geometry>
        <mesh
          filename="package://hsr_co602a_gaihou/meshes/base_link.STL" />
      </geometry>
      <material
        name="">
        <color
          rgba="1 1 1 1" />
      </material>
    </visual>
    <collision>
      <origin
        xyz="0 0 0"
        rpy="0 0 0" />
      <geometry>
        <mesh
          filename="package://hsr_co602a_gaihou/meshes/base_link.STL" />
      </geometry>
    </collision>
  </link>
  <link
    name="R_link1">
    <inertial>
      <origin
        xyz="-3.5083E-06 -0.029409 0.065583"
        rpy="0 0 0" />
      <mass
        value="4.9043" />
      <inertia
        ixx="0"
        ixy="0"
        ixz="0"
        iyy="0"
        iyz="0"
        izz="0" />
    </inertial>
    <visual>
      <origin
        xyz="0 0 0"
        rpy="0 0 0" />
      <geometry>
        <mesh
          filename="package://hsr_co602a_gaihou/meshes/Link1.STL" />
      </geometry>
      <material
        name="">
        <color
          rgba="1 1 1 1" />
      </material>
    </visual>
    <collision>
      <origin
        xyz="0 0 0"
        rpy="0 0 0" />
      <geometry>
        <mesh
          filename="package://hsr_co602a_gaihou/meshes/Link1.STL" />
      </geometry>
    </collision>
  </link>
  <joint
    name="R_joint_1"
    type="revolute">
    <origin
      xyz="0 0 0.3517"
      rpy="3.1416 0 -8.3267E-17" />
    <parent
      link="base_link2" />
    <child
      link="R_link1" />
    <axis
      xyz="0 0 -1" />
    <limit
      lower="-3.490658503988"
      upper="3.490658503988"
      effort="28"
      velocity="3.2" />
    <safety_controller
      soft_upper_limit="3.481931857728"
      soft_lower_limit="-3.481931857728"
      k_position="100"
      k_velocity="10" />
  </joint>
  <link
    name="R_link2">
    <inertial>
      <origin
        xyz="4.8764E-06 -0.17949 -0.038569"
        rpy="0 0 0" />
      <mass
        value="6.5305" />
      <inertia
        ixx="0"
        ixy="0"
        ixz="0"
        iyy="0"
        iyz="0"
        izz="0" />
    </inertial>
    <visual>
      <origin
        xyz="0 0 0"
        rpy="0 0 0" />
      <geometry>
        <mesh
          filename="package://hsr_co602a_gaihou/meshes/Link2.STL" />
      </geometry>
      <material
        name="">
        <color
          rgba="1 1 1 1" />
      </material>
    </visual>
    <collision>
      <origin
        xyz="0 0 0"
        rpy="0 0 0" />
      <geometry>
        <mesh
          filename="package://hsr_co602a_gaihou/meshes/Link2.STL" />
      </geometry>
    </collision>
  </link>
  <joint
    name="R_joint_2"
    type="revolute">
    <origin
      xyz="0 0 0"
      rpy="1.5708 -1.5708 0" />
    <parent
      link="R_link1" />
    <child
      link="R_link2" />
    <axis
      xyz="0 0 1" />
    <limit
      lower="-2.268928027592"
      upper="1"
      effort="28"
      velocity="3.2" />
    <safety_controller
      soft_upper_limit="1"
      soft_lower_limit="-2.260201381332"
      k_position="100"
      k_velocity="10" />
  </joint>
  <link
    name="R_link3">
    <inertial>
      <origin
        xyz="-4.0966E-05 -0.085254 -0.035956"
        rpy="0 0 0" />
      <mass
        value="2.3223" />
      <inertia
        ixx="0"
        ixy="0"
        ixz="0"
        iyy="0"
        iyz="0"
        izz="0" />
    </inertial>
    <visual>
      <origin
        xyz="0 0 0"
        rpy="0 0 0" />
      <geometry>
        <mesh
          filename="package://hsr_co602a_gaihou/meshes/Link3.STL" />
      </geometry>
      <material
        name="">
        <color
          rgba="1 1 1 1" />
      </material>
    </visual>
    <collision>
      <origin
        xyz="0 0 0"
        rpy="0 0 0" />
      <geometry>
        <mesh
          filename="package://hsr_co602a_gaihou/meshes/Link3.STL" />
      </geometry>
    </collision>
  </link>
  <joint
    name="R_joint_3"
    type="revolute">
    <origin
      xyz="0 -0.40061 0"
      rpy="-3.688E-17 1.4367E-17 -1.5708" />
    <parent
      link="R_link2" />
    <child
      link="R_link3" />
    <axis
      xyz="0 0 1" />
    <limit
      lower="1"
      upper="3.665191429188"
      effort="28"
      velocity="3.2" />
    <safety_controller
      soft_upper_limit="3.656464782928"
      soft_lower_limit="0.008726646259"
      k_position="100"
      k_velocity="10" />
  </joint>
  <link
    name="R_link4">
    <inertial>
      <origin
        xyz="0.049764 2.8231E-06 0.32133"
        rpy="0 0 0" />
      <mass
        value="1.2629" />
      <inertia
        ixx="0"
        ixy="0"
        ixz="0"
        iyy="0"
        iyz="0"
        izz="0" />
    </inertial>
    <visual>
      <origin
        xyz="0 0 0"
        rpy="0 0 0" />
      <geometry>
        <mesh
          filename="package://hsr_co602a_gaihou/meshes/Link4.STL" />
      </geometry>
      <material
        name="">
        <color
          rgba="1 1 1 1" />
      </material>
    </visual>
    <collision>
      <origin
        xyz="0 0 0"
        rpy="0 0 0" />
      <geometry>
        <mesh
          filename="package://hsr_co602a_gaihou/meshes/Link4.STL" />
      </geometry>
    </collision>
  </link>
  <joint
    name="R_joint_4"
    type="revolute">
    <origin
      xyz="0 -0.0023254 0"
      rpy="1.2216 1.5708 -0.34916" />
    <parent
      link="R_link3" />
    <child
      link="R_link4" />
    <axis
      xyz="0 0 1" />
    <limit
      lower="-1.0"
      upper="3.0"
      effort="28"
      velocity="3.2" />
    <safety_controller
      soft_upper_limit="3.0"
      soft_lower_limit="-3.0"
      k_position="100"
      k_velocity="10" />
  </joint>
  <link
    name="R_link5">
    <inertial>
      <origin
        xyz="1.3212E-06 -0.042021 0.0022165"
        rpy="0 0 0" />
      <mass
        value="1.1452" />
      <inertia
        ixx="0"
        ixy="0"
        ixz="0"
        iyy="0"
        iyz="0"
        izz="0" />
    </inertial>
    <visual>
      <origin
        xyz="0 0 0"
        rpy="0 0 0" />
      <geometry>
        <mesh
          filename="package://hsr_co602a_gaihou/meshes/Link5.STL" />
      </geometry>
      <material
        name="">
        <color
          rgba="1 1 1 1" />
      </material>
    </visual>
    <collision>
      <origin
        xyz="0 0 0"
        rpy="0 0 0" />
      <geometry>
        <mesh
          filename="package://hsr_co602a_gaihou/meshes/Link5.STL" />
      </geometry>
    </collision>
  </link>
  <joint
    name="R_joint_5"
    type="revolute">
    <origin
      xyz="0 0 0.39859"
      rpy="-1.5708 -1.4529E-17 1.5708" />
    <parent
      link="R_link4" />
    <child
      link="R_link5" />
    <axis
      xyz="0 0 1" />
    <limit
      lower="-2.268928027592"
      upper="2.268928027592"
      effort="28"
      velocity="3.2" />
    <safety_controller
      soft_upper_limit="2.260201381332"
      soft_lower_limit="-2.260201381332"
      k_position="100"
      k_velocity="10" />
  </joint>
  <link
    name="R_link6">
    <inertial>
      <origin
        xyz="3.5784E-05 -3.8806E-05 -0.025197"
        rpy="0 0 0" />
      <mass
        value="0.20458" />
      <inertia
        ixx="0"
        ixy="0"
        ixz="0"
        iyy="0"
        iyz="0"
        izz="0" />
    </inertial>
    <visual>
      <origin
        xyz="0 0 0"
        rpy="0 0 0" />
      <geometry>
        <mesh
          filename="package://hsr_co602a_gaihou/meshes/Link6.STL" />
      </geometry>
      <material
        name="">
        <color
          rgba="1 1 1 1" />
      </material>
    </visual>
    <collision>
      <origin
        xyz="0 0 0"
        rpy="0 0 0" />
      <geometry>
        <mesh
          filename="package://hsr_co602a_gaihou/meshes/Link6.STL" />
      </geometry>
    </collision>
  </link>
  <joint
    name="R_joint_6"
    type="revolute">
    <origin
      xyz="0 -0.20056 0"
      rpy="-1.5708 2.4478E-17 -3.1416" />
    <parent
      link="R_link5" />
    <child
      link="R_link6" />
    <axis
      xyz="0 0 1" />
    <limit
      lower="-5.1"
      upper="5.1"
      effort="28"
      velocity="3.2" />
    <safety_controller
      soft_upper_limit="5.1"
      soft_lower_limit="-5.1"
      k_position="100"
      k_velocity="10" />
  </joint>
</robot>