<robot
  name="hsr_co602a_gaihou">
  <link
    name="base_link">
    <inertial>
      <origin
        xyz="-0.0024613 5.2375E-07 0.076752"
        rpy="0 0 0" />
      <mass
        value="4.8818" />
      <inertia
        ixx="0"
        ixy="0"
        ixz="0"
        iyy="0"
        iyz="0"
        izz="0" />
    </inertial>
    <visual>
      <origin
        xyz="0 0 0"
        rpy="0 0 0" />
      <geometry>
        <mesh
          filename="package://hsr_co602a_gaihou/meshes/base_link.STL" />
      </geometry>
      <material
        name="">
        <color
          rgba="1 1 1 1" />
      </material>
    </visual>
    <collision>
      <origin
        xyz="0 0 0"
        rpy="0 0 0" />
      <geometry>
        <mesh
          filename="package://hsr_co602a_gaihou/meshes/base_link.STL" />
      </geometry>
    </collision>
  </link>
  <link
    name="Link1">
    <inertial>
      <origin
        xyz="-3.5083E-06 -0.029409 0.065583"
        rpy="0 0 0" />
      <mass
        value="4.9043" />
      <inertia
        ixx="0"
        ixy="0"
        ixz="0"
        iyy="0"
        iyz="0"
        izz="0" />
    </inertial>
    <visual>
      <origin
        xyz="0 0 0"
        rpy="0 0 0" />
      <geometry>
        <mesh
          filename="package://hsr_co602a_gaihou/meshes/Link1.STL" />
      </geometry>
      <material
        name="">
        <color
          rgba="1 1 1 1" />
      </material>
    </visual>
    <collision>
      <origin
        xyz="0 0 0"
        rpy="0 0 0" />
      <geometry>
        <mesh
          filename="package://hsr_co602a_gaihou/meshes/Link1.STL" />
      </geometry>
    </collision>
  </link>
  <joint
    name="joint1"
    type="revolute">
    <origin
      xyz="0 0 0.3517"
      rpy="3.1416 0 -8.3267E-17" />
    <parent
      link="base_link" />
    <child
      link="Link1" />
    <axis
      xyz="0 0 -1" />
    <limit
      lower="-1.57"
      upper="1.57"
      effort="3"
      velocity="26" />
    <safety_controller
      soft_upper="1.57"
      soft_lower="-1.57"
      k_position="6"
      k_velocity="10" />
  </joint>
  <link
    name="Link2">
    <inertial>
      <origin
        xyz="4.8764E-06 -0.17949 -0.038569"
        rpy="0 0 0" />
      <mass
        value="6.5305" />
      <inertia
        ixx="0"
        ixy="0"
        ixz="0"
        iyy="0"
        iyz="0"
        izz="0" />
    </inertial>
    <visual>
      <origin
        xyz="0 0 0"
        rpy="0 0 0" />
      <geometry>
        <mesh
          filename="package://hsr_co602a_gaihou/meshes/Link2.STL" />
      </geometry>
      <material
        name="">
        <color
          rgba="1 1 1 1" />
      </material>
    </visual>
    <collision>
      <origin
        xyz="0 0 0"
        rpy="0 0 0" />
      <geometry>
        <mesh
          filename="package://hsr_co602a_gaihou/meshes/Link2.STL" />
      </geometry>
    </collision>
  </link>
  <joint
    name="joint2"
    type="revolute">
    <origin
      xyz="0 0 0"
      rpy="1.5708 -1.5708 0" />
    <parent
      link="Link1" />
    <child
      link="Link2" />
    <axis
      xyz="0 0 -1" />
    <limit
      lower="-1.57"
      upper="1.57"
      effort="3"
      velocity="26" />
    <safety_controller
      soft_upper="1.57"
      soft_lower="-1.57"
      k_position="6"
      k_velocity="10" />
  </joint>
  <link
    name="Link3">
    <inertial>
      <origin
        xyz="-4.0966E-05 -0.085254 -0.035956"
        rpy="0 0 0" />
      <mass
        value="2.3223" />
      <inertia
        ixx="0"
        ixy="0"
        ixz="0"
        iyy="0"
        iyz="0"
        izz="0" />
    </inertial>
    <visual>
      <origin
        xyz="0 0 0"
        rpy="0 0 0" />
      <geometry>
        <mesh
          filename="package://hsr_co602a_gaihou/meshes/Link3.STL" />
      </geometry>
      <material
        name="">
        <color
          rgba="1 1 1 1" />
      </material>
    </visual>
    <collision>
      <origin
        xyz="0 0 0"
        rpy="0 0 0" />
      <geometry>
        <mesh
          filename="package://hsr_co602a_gaihou/meshes/Link3.STL" />
      </geometry>
    </collision>
  </link>
  <joint
    name="joint3"
    type="revolute">
    <origin
      xyz="0 -0.40061 0"
      rpy="-3.688E-17 1.4367E-17 -1.5708" />
    <parent
      link="Link2" />
    <child
      link="Link3" />
    <axis
      xyz="0 0 -1" />
    <limit
      lower="-1.57"
      upper="1.57"
      effort="3"
      velocity="26" />
    <safety_controller
      soft_upper="1.57"
      soft_lower="-1.57"
      k_position="6"
      k_velocity="10" />
  </joint>
  <link
    name="Link4">
    <inertial>
      <origin
        xyz="0.049764 2.8231E-06 0.32133"
        rpy="0 0 0" />
      <mass
        value="1.2629" />
      <inertia
        ixx="0"
        ixy="0"
        ixz="0"
        iyy="0"
        iyz="0"
        izz="0" />
    </inertial>
    <visual>
      <origin
        xyz="0 0 0"
        rpy="0 0 0" />
      <geometry>
        <mesh
          filename="package://hsr_co602a_gaihou/meshes/Link4.STL" />
      </geometry>
      <material
        name="">
        <color
          rgba="1 1 1 1" />
      </material>
    </visual>
    <collision>
      <origin
        xyz="0 0 0"
        rpy="0 0 0" />
      <geometry>
        <mesh
          filename="package://hsr_co602a_gaihou/meshes/Link4.STL" />
      </geometry>
    </collision>
  </link>
  <joint
    name="joint4"
    type="revolute">
    <origin
      xyz="0 -0.0023254 0"
      rpy="1.2216 1.5708 -0.34916" />
    <parent
      link="Link3" />
    <child
      link="Link4" />
    <axis
      xyz="0 0 1" />
    <limit
      lower="-1.57"
      upper="1.57"
      effort="3"
      velocity="26" />
    <safety_controller
      soft_upper="1.57"
      soft_lower="-1.57"
      k_position="6"
      k_velocity="10" />
  </joint>
  <link
    name="Link5">
    <inertial>
      <origin
        xyz="1.3212E-06 -0.042021 0.0022165"
        rpy="0 0 0" />
      <mass
        value="1.1452" />
      <inertia
        ixx="0"
        ixy="0"
        ixz="0"
        iyy="0"
        iyz="0"
        izz="0" />
    </inertial>
    <visual>
      <origin
        xyz="0 0 0"
        rpy="0 0 0" />
      <geometry>
        <mesh
          filename="package://hsr_co602a_gaihou/meshes/Link5.STL" />
      </geometry>
      <material
        name="">
        <color
          rgba="1 1 1 1" />
      </material>
    </visual>
    <collision>
      <origin
        xyz="0 0 0"
        rpy="0 0 0" />
      <geometry>
        <mesh
          filename="package://hsr_co602a_gaihou/meshes/Link5.STL" />
      </geometry>
    </collision>
  </link>
  <joint
    name="joint5"
    type="revolute">
    <origin
      xyz="0 0 0.39859"
      rpy="-1.5708 -1.4529E-17 1.5708" />
    <parent
      link="Link4" />
    <child
      link="Link5" />
    <axis
      xyz="0 0 -1" />
    <limit
      lower="-1.57"
      upper="1.57"
      effort="3"
      velocity="26" />
    <safety_controller
      soft_upper="1.57"
      soft_lower="-1.57"
      k_position="6"
      k_velocity="10" />
  </joint>
  <link
    name="Link6">
    <inertial>
      <origin
        xyz="3.5784E-05 -3.8806E-05 -0.025197"
        rpy="0 0 0" />
      <mass
        value="0.20458" />
      <inertia
        ixx="0"
        ixy="0"
        ixz="0"
        iyy="0"
        iyz="0"
        izz="0" />
    </inertial>
    <visual>
      <origin
        xyz="0 0 0"
        rpy="0 0 0" />
      <geometry>
        <mesh
          filename="package://hsr_co602a_gaihou/meshes/Link6.STL" />
      </geometry>
      <material
        name="">
        <color
          rgba="1 1 1 1" />
      </material>
    </visual>
    <collision>
      <origin
        xyz="0 0 0"
        rpy="0 0 0" />
      <geometry>
        <mesh
          filename="package://hsr_co602a_gaihou/meshes/Link6.STL" />
      </geometry>
    </collision>
  </link>
  <joint
    name="joint6"
    type="revolute">
    <origin
      xyz="0 -0.20056 0"
      rpy="-1.5708 2.4478E-17 -3.1416" />
    <parent
      link="Link5" />
    <child
      link="Link6" />
    <axis
      xyz="0 0 -1" />
    <limit
      lower="-1.57"
      upper="1.57"
      effort="3"
      velocity="26" />
    <safety_controller
      soft_upper="1.57"
      soft_lower="-1.57"
      k_position="6"
      k_velocity="10" />
  </joint>
</robot>